Workbook

Sheet Sheet1
A1: Name | B1: Measure | C1: Tags | D1: Tags old | E1: change | F1: TagNumber | G1: German name | H1: DO THESE Exist in IDI?
A2: MBS Current reel ID | C2: QO-REEL-ID-CUR-CALC | D2: QO-REEL-ID-CUR-CALC | E2: =IF(C2=D2,1,0) -> 1 | F2: 12576 | G2: Virtual Online JumboID MachineID + Year(2digits) + QLS-REEL-ID-CUR
A3: AB Grade ID | C3: GRADE_NAME | D3: GRADE_NAME | E3: =IF(C3=D3,1,0) -> 1 | F3: 14082 | G3: Sortenname [0..9999999 ]
A4: MBS SCT CD | C4: QO_SCT_CD | D4: QO_SCT_CD | E4: =IF(C4=D4,1,0) -> 1 | F4: 18118 | G4: QO_SCT CD SCT in Querrichtung SCT CD :38
A5: MBS SCT MD | C5: QO_SCT_MD | D5: QO_SCT_MD | E5: =IF(C5=D5,1,0) -> 1 | F5: 18119 | G5: QO_SCT MD SCT in Maschinenrichtung SCT MD :39
A6: MBS Burst | C6: QO_BERSTWIDERSTAND | D6: QO_BERSTWIDERSTAND | E6: =IF(C6=D6,1,0) -> 1 | F6: 18078 | G6: QO_Berstwiderstand Berstwiderstand Berstwiderstand :6
A7: MBS CMT30 | C7: QO_CMT | D7: QO_CMT | E7: =IF(C7=D7,1,0) -> 1 | F7: 18081 | G7: QO_CMT CMT Presse CMT :10
A8: Stock pump power | B8: A | C8: 2-008-P041_10-XI | D8: 2-008-P041_10-XI | E8: =IF(C8=D8,1,0) -> 1 | F8: 13718 | G8: Strom Stoffauflaufpumpe [0..1260 A]
A9: O=Alles OK sonst Abrissort li:PM1-OPC-DATA.F:break_location | C9: PM1_ABRISS-ERKENNUNG | D9: PM1_ABRISS-ERKENNUNG | E9: =IF(C9=D9,1,0) -> 1 | F9: 8312 | G9: O=Alles OK sonst Abrissort li:PM1-OPC-DATA.F:break_location
A10: Speed | B10: m/min | C10: 2-008-VPOPE-AR0 | D10: 2-008-VPOPE-AR0 | E10: =IF(C10=D10,1,0) -> 1 | F10: 14345 | G10: Geschwindigkeit Poperoller_Abriss_0 [0..1500 m/min]
A11: Current reel weight | B11: Kg | C11: QO-REEL-WEIGHT-CUR | D11: QO-REEL-WEIGHT-CUR | E11: =IF(C11=D11,1,0) -> 1 | F11: 36 | G11: Current reel weight
A12: Current reel width | B12: CM | C12: QLS-REEL-WIDTH-CUR | D12: QLS-REEL-WIDTH-CUR | E12: =IF(C12=D12,1,0) -> 1 | F12: 37 | G12: Current reel width
A13: Current reel length | B13: M | C13: QO-REEL-LENGTH-CUR | D13: QO-REEL-LENGTH-CUR | E13: =IF(C13=D13,1,0) -> 1 | F13: 28 | G13: Current reel length
A14: Production Rate [T/h] | B14: t/h | C14: PRODUCTION-RATE | D14: PRODUCTION-RATE | E14: =IF(C14=D14,1,0) -> 1 | F14: 10438 | G14: Produktions Rate 2 [0..90 t/h]
A15: Current basis weight | B15: G/M2 | C15: QMS11_SCN1QM1-X | D15: QMS11_SCN1QM1-X | E15: =IF(C15=D15,1,0) -> 1 | F15: 11237 | G15: IST Flächengewicht g/m2
A16: Current reel moisture average(reel) | C16: QLS-REEL-MOISTURE1-CUR | D16: QLS-REEL-MOISTURE1-CUR | E16: =IF(C16=D16,1,0) -> 1 | F16: 40 | G16: Current reel moisture average(Aufrollung)
A17: Actual moisture | B17: PCT | C17: QMS11_MIC_MSTSCN1-X1 | D17: QMS11_MIC_MSTSCN1-X1 | E17: =IF(C17=D17,1,0) -> 1 | F17: 11385 | G17: Feuchte NTP Poperoller 0-15 %
A18: Current reel dry average | C18: QLS-REEL-DRY-CUR | D18: QLS-REEL-DRY-CUR | E18: =IF(C18=D18,1,0) -> 1 | F18: 42 | G18: Current reel dry average
A19: BSW 2 sigma | C19: PM1-BW1-RL:GFLT.SIG | D19: PM1-BW1-RL:GFLT.SIG | E19: =IF(C19=D19,1,0) -> 1 | F19: 18254 | G19: FLG Messung gefiltertes Profil 2 sigma [0..20 ]
A20: Mois Size Press 2 sigma | C20: PM1-PM1-SP:GFLT.SIG | D20: PM1-PM1-SP:GFLT.SIG | E20: =IF(C20=D20,1,0) -> 1 | F20: 18291 | G20: Feuchtemessung Sizer gefiltertes Profil 2 sigma [0..20 ]
A21: Mois 2 sigma | C21: PM1-MO1-RL:GFLT.SIG | D21: PM1-MO1-RL:GFLT.SIG | E21: =IF(C21=D21,1,0) -> 1 | F21: 18273 | G21: Feuchtemessung Pope gefiltertes Profil 2 sigma [0..20 ]
A22: Contact pressure reel holders | B22: KN/M | C22: 2-060-YP045-X | D22: 2-060-YP045-X | E22: =IF(C22=D22,1,0) -> 1 | F22: 9875 | G22: 2-060-YP045 Anpreßdr Tambhalter : Messwert
A23: Reel discharge pressure | B23: BAR | C23: 2-060-YP048-X | D23: 2-060-YP048-X | E23: =IF(C23=D23,1,0) -> 1 | F23: 9876 | G23: 2-060-YP048 Tambourentlastung : Messwert
A24: Draw meaurement pope reel FS | B24: N/m | C24: 2-060-NI001-X | D24: 2-060-NI001-X | E24: =IF(C24=D24,1,0) -> 1 | F24: 10289 | G24: Zugmessung FS Poperoller : Messwert [0..1000 N/m]
A25: Draw measurement pope reel DS | B25: N/m | C25: 2-060-NI002-X | D25: 2-060-NI002-X | E25: =IF(C25=D25,1,0) -> 1 | F25: 10290 | G25: Zugmessung TS Poperoller : Messwert [0..1000 N/m]
A26: Total draw measurement pope reel | B26: N/m | C26: 2-060-NI003-X | D26: 2-060-NI003-X | E26: =IF(C26=D26,1,0) -> 1 | F26: 10291 | G26: Zugmessung gesamt Poperoller : Messwert [0..1000 N/m]
A27: Contact pressure support drum OS | B27: KN | C27: 2-060-WC050_01-X | D27: 2-060-WC050_01-X | E27: =IF(C27=D27,1,0) -> 1
A28: Contact pressure support drum DS | B28: KN | C28: 2-060-WC050_02-X | D28: 2-060-WC050_02-X | E28: =IF(C28=D28,1,0) -> 1
A29: Contact pressure secondary arm OS | B29: BAR | C29: 2-060-YP052_01-X | D29: 2-060-YP052_01-X | E29: =IF(C29=D29,1,0) -> 1 | F29: 9877 | G29: 2-060-YP052.01 Anpreßdr Sek-Arm FS : Messwert
A30: Contact pressure secondary arm DS | B30: BAR | C30: 2-060-YP052_02-X | D30: 2-060-YP052_02-X | E30: =IF(C30=D30,1,0) -> 1 | F30: 9878 | G30: 2-060-YP052.02 Anpreßdr Sek-Arm TS : Messwert
A31: Retentionsmittel Menge l/h [0..9000 l/h] | C31: 2-008-FC083.01-X | D31: 2-008-FC083.01-X | E31: =IF(C31=D31,1,0) -> 1 | F31: 10035 | G31: Retentionsmittel Menge l/h [0..9000 l/h]
A32: Bentonitmenge z. Mischrohr [-10..9000 l/h] | C32: 2-008-FC080_10_1-X | D32: 2-008-FC080_10_1-X | E32: =IF(C32=D32,1,0) -> 1 | F32: 13199 | G32: Bentonitmenge z. Mischrohr [-10..9000 l/h]
A33: Bentonitmenge z. Siebwasserturm [-10..9000 l/h] | C33: 2-008-FC080_10_2-X | D33: 2-008-FC080_10_2-X | E33: =IF(C33=D33,1,0) -> 1 | F33: 13216 | G33: Bentonitmenge z. Siebwasserturm [-10..9000 l/h]
A34: Sollwert Fixiermittelmenge [-1..50 l/h] | C34: 2-008-FIXIER-SOLL | D34: 2-008-FIXIER-SOLL | E34: =IF(C34=D34,1,0) -> 1
A35: Fixiermittelmenge Trockenausschuss [0..100 l/h] | C35: 2-008-FC080_02_3-X | D35: 2-008-FC080_02_3-X | E35: =IF(C35=D35,1,0) -> 1 | F35: 14084 | G35: Fixiermittelmenge Trockenausschuss [0..100 l/h]
A36: Mengenregelung Entlüfter : MESSWERT [0..40 l/h] | C36: 2-008-FC086_01-X | D36: 2-008-FC086_01-X | E36: =IF(C36=D36,1,0) -> 1 | F36: 15449 | G36: Mengenregelung Entlüfter : MESSWERT [0..40 l/h]
A37: Starch uptake by paper Top Roll [g/m2] | C37: 2-033-FI200-G_M2 | D37: 2-033-FI200-G_M2 | E37: =IF(C37=D37,1,0) -> 1 | F37: 13221 | G37: Stärkeauftrag bewegliche Walze [g / m²] [0..50 g/m²]
A38: Starch uptake by paper Bottom Roll [g/m2] | C38: 2-033-FI100-G_M2 | D38: 2-033-FI100-G_M2 | E38: =IF(C38=D38,1,0) -> 1 | F38: 13220 | G38: Stärkeauftrag feste Walze [g / m²] [0..50 g/m²]
A39: Paper break status li:PM1-OPC-DATA.F:rtup_pls (0 = false) | C39: QLS-PM1-BREAK-STATUS2 | D39: QLS-PM1-BREAK-STATUS2 | E39: =IF(C39=D39,1,0) -> 1 | F39: 8171 | G39: Paper break status li:PM1-OPC-DATA.F:rtup_pls (0 = false)
A40: Entschäumermenge FW [-1..60 l/h] | C40: 2-008-FI080_03_3-X | D40: 2-008-FI080_03_3-X | E40: =IF(C40=D40,1,0) -> 1 | F40: 13236 | G40: Entschäumermenge FW [-1..60 l/h]
...

Sheet Sheet3
A4: Row Labels
A5: 1-000-A001_37-X
A6: 1-000-A001_35-X
A7: 1-000-A001_38-X
A8: 1-000-A001_36-X
A9: 1-000-A004_3-X
A10: 1-000-A001_37-X
A11: 1-000-A005_10-WG
A12: 1-000-A004_3-X
A13: 1-000-A005_11-WG
A14: 1-000-A005_11-X
A15: 1-000-A005_11-X
... A1142: Grand Total

Sheet New List of Tags vs IDI
A1: Tags | B1: Sensor/Calculation Tag | H1: IDI Tags | I1: R&D Tags | J1: TAGS THAT MATCH (R&D = IDI)
A2: 1-000-A001_35-X | B2: 1-000-A001_37-X | H2: 1-000-A005_10-WG | I2: 1-000-A004_3-X | J2: =IFERROR(VLOOKUP(Table358[[#This Row],[R&D Tags]],'Old List of R&D Tags vs IDI'!H:H,1,FALSE), " ") -> QMS11_SCN1QM1-X
A3: 1-000-A001_36-X | B3: 1-000-A001_38-X | H3: 1-000-A005_11-WG | I3: 1-000-A005_11-X | J3: =IFERROR(VLOOKUP(Table35[[#This Row],[R&D Tags]],H:H,1,FALSE), " ") -> 1-000-A005_11-X
A4: 1-000-A001_37-X | B4: 1-000-A004_3-X | H4: 1-000-A005_15-WG | I4: 1-000-CC005_1_1-X | J4: =IFERROR(VLOOKUP(Table35[[#This Row],[R&D Tags]],H:H,1,FALSE), " ") -> 1-000-CC005_1_1-X | L4: Out of 588 tags 300 match from R&D
A5: 1-000-A004_3-X | B5: 1-000-A005_10-WG | H5: 1-000-A005_15-X | I5: 1-000-CC005_1_2-X | J5: =IFERROR(VLOOKUP(Table35[[#This Row],[R&D Tags]],H:H,1,FALSE), " ") -> 1-000-CC005_1_2-X | L5: so 24 R&D tags are not in the IDI
A6: 1-000-A005_11-X | B6: 1-000-A005_11-WG | H6: 1-000-A005_40-N | I6: 1-000-CC005_1_3-X | J6: =IFERROR(VLOOKUP(Table35[[#This Row],[R&D Tags]],H:H,1,FALSE), " ") -> 1-000-CC005_1_3-X
A7: 1-000-CC001_1-X | B7: 1-000-A005_11-X | H7: 1-000-A005_9-WG | I7: 1-000-CC006_01-X | J7: =IFERROR(VLOOKUP(Table35[[#This Row],[R&D Tags]],H:H,1,FALSE), " ") -> 1-000-CC006_01-X
A8: 1-000-CC005_1_1-X | B8: 1-000-A005_15-WG | H8: 1-000-CC001_30-X | I8: 1-000-CC007_01-X | J8: =IFERROR(VLOOKUP(Table35[[#This Row],[R&D Tags]],H:H,1,FALSE), " ") -> 1-000-CC007_01-X
A9: 1-000-CC005_1_2-X | B9: 1-000-A005_15-X | H9: 1-000-CC002_1-X | I9: 1-000-EI002_1-X | J9: =IFERROR(VLOOKUP(Table35[[#This Row],[R&D Tags]],H:H,1,FALSE), " ") -> 1-000-EI002_1-X
A10: 1-000-CC005_1_3-X | B10: 1-000-A005_40-N | H10: 1-000-EI003_1-X | I10: 1-000-FC005_1-X | J10: =IFERROR(VLOOKUP(Table35[[#This Row],[R&D Tags]],H:H,1,FALSE), " ") -> 1-000-FC005_1-X
A11: 1-000-CC006_01-X | B11: 1-000-A005_9-WG | H11: 1-000-EI005_9_2-X | I11: 1-000-FC005_8_1-X | J11: =IFERROR(VLOOKUP(Table35[[#This Row],[R&D Tags]],H:H,1,FALSE), " ") -> 1-000-FC005_8_1-X
A12: 1-000-CC007_01-X | B12: 1-000-CC001_30-X | H12: 1-000-FC005_12-X | I12: 1-000-FC028_02-X | J12: =IFERROR(VLOOKUP(Table35[[#This Row],[R&D Tags]],H:H,1,FALSE), " ") -> 1-000-FC028_02-X
A13: 1-000-EI002_1-X | B13: 1-000-CC002_1-X | H13: 1-000-FC005_16-X | I13: 1-000-FI005_9_1-X | J13: =IFERROR(VLOOKUP(Table35[[#This Row],[R&D Tags]],H:H,1,FALSE), " ") -> 1-000-FI005_9_1-X
A14: 1-000-EI004_1-X | B14: 1-000-CC005_1_1-X | H14: 1-000-FC005_17-X | I14: 1-000-PI002_2DP-X | J14: =IFERROR(VLOOKUP(Table35[[#This Row],[R&D Tags]],H:H,1,FALSE), " ") -> 1-000-PI002_2DP-X
A15: 1-000-EI004_2-X | B15: 1-000-CC005_1_2-X | H15: 1-000-FC011_20-X | I15: 2-000-2A1J16-P | J15: =IFERROR(VLOOKUP(Table35[[#This Row],[R&D Tags]],H:H,1,FALSE), " ") -> 2-000-2A1J16-P
A16: 1-000-EI005_10-X | B16: 1-000-CC005_1_3-X | H16: 1-000-FC016_1-X | I16: 2-000-2A1J17-P | J16: =IFERROR(VLOOKUP(Table35[[#This Row],[R&D Tags]],H:H,1,FALSE), " ") -> 2-000-2A1J17-P
A17: 1-000-EI005_9_1-X | B17: 1-000-CC006_01-X | H17: 1-000-FC018_2-X | I17: 2-000-2A1J18-P | J17: =IFERROR(VLOOKUP(Table35[[#This Row],[R&D Tags]],H:H,1,FALSE), " ") -> 2-000-2A1J18-P
... A325: PM1_2-346-YP043-X | B325: 2-044-TI704_NL | H325: 2-076-FC25_01 | I325: QO-REEL-CURR-AVG-WEBWIDTH | J325: =IFERROR(VLOOKUP(Table35[[#This Row],[R&D Tags]],H:H,1,FALSE), " ")
A326: PM1_ABRISS-ERKENNUNG | B326: 2-060-ANTRIEB42 | H326: 2-076-QI050_01 | J326: =IFERROR(VLOOKUP(Table35[[#This Row],[R&D Tags]],H:H,1,FALSE), " ")
A327: PM1-BW1-RL:GFLT.SIG | B327: 2-060-GI056-D1 | H327: 2-104-ANTRIEB10-KW | J327: =IFERROR(VLOOKUP(Table35[[#This Row],[R&D Tags]],H:H,1,FALSE), " ")
A328: PM1-MO1-RL:GFLT.SIG | B328: 2-060-NI001-X | H328: 2-104-ANTRIEB11-KW | J328: =IFERROR(VLOOKUP(Table35[[#This Row],[R&D Tags]],H:H,1,FALSE), " ")
A329: PM1-PM1-SP:GFLT.SIG | B329: 2-060-NI002-X | H329: 2-104-FI001-X | J329: =IFERROR(VLOOKUP(Table35[[#This Row],[R&D Tags]],H:H,1,FALSE), " ")
A330: PRODUCTION-RATE | B330: 2-060-NI003-X | H330: 2-104-NC010_1-IST_POS | J330: =IFERROR(VLOOKUP(Table35[[#This Row],[R&D Tags]],H:H,1,FALSE), " ")
A331: QLS-PM1-BREAK-STATUS2 | B331: 2-060-UZ011-941 | H331: 2-104-NC010_2-IST_POS | J331: =IFERROR(VLOOKUP(Table35[[#This Row],[R&D Tags]],H:H,1,FALSE), " ")
A332: QLS-REEL-DRY-CUR | B332: 2-060-UZ011-D1 | H332: 2-146-YP043-D6 | J332: =IFERROR(VLOOKUP(Table35[[#This Row],[R&D Tags]],H:H,1,FALSE), " ")
A333: QLS-REEL-MOISTURE1-CUR | B333: 2-060-WC050_01-X | H333: 2-199-P071_2-X | J333: =IFERROR(VLOOKUP(Table35[[#This Row],[R&D Tags]],H:H,1,FALSE), " ")
A334: QLS-REEL-MOISTURE2-CUR | B334: 2-060-WC050_02-X | H334: 2-199-PI061-X | J334: =IFERROR(VLOOKUP(Table35[[#This Row],[R&D Tags]],H:H,1,FALSE), " ")
A335: QLS-REEL-WIDTH-CUR | B335: 2-060-YP045-X | H335: 2-199-PI062-X | J335: =IFERROR(VLOOKUP(Table35[[#This Row],[R&D Tags]],H:H,1,FALSE), " ")
A336: QMS11_2-008-QC041.05.01-X | B336: 2-060-YP048-X | H336: 2-199-PI063-X | J336: =IFERROR(VLOOKUP(Table35[[#This Row],[R&D Tags]],H:H,1,FALSE), " ")
A337: QMS11_2-009-FI200.01.2-X | B337: 2-060-YP052_01-X | H337: 2-199-PI067-X | J337: =IFERROR(VLOOKUP(Table35[[#This Row],[R&D Tags]],H:H,1,FALSE), " ")
... A367: STAERKE_FW | B367: 2-076-LC061_01-X | H367: 2-404-NC011_2-IST_POS | J367: =IFERROR(VLOOKUP(Table35[[#This Row],[R&D Tags]],H:H,1,FALSE), " ")
B368: 2-076-LI050_01-X | H368: 2-504-ANTRIEB22-KW | J368: =IFERROR(VLOOKUP(Table35[[#This Row],[R&D Tags]],H:H,1,FALSE), " ")
B369: 2-076-PC040_01-X | H369: 2-504-ANTRIEB23-KW | J369: =IFERROR(VLOOKUP(Table35[[#This Row],[R&D Tags]],H:H,1,FALSE), " ")
B370: 2-076-PC050_01-X | H370: 2-504-ANTRIEB24-KW | J370: =IFERROR(VLOOKUP(Table35[[#This Row],[R&D Tags]],H:H,1,FALSE), " ")
B371: 2-076-PC070_01-X | H371: 2-504-ANTRIEB25-KW | J371: =IFERROR(VLOOKUP(Table35[[#This Row],[R&D Tags]],H:H,1,FALSE), " ")
B372: 2-076-PI021_01-X | H372: 2-504-ANTRIEB26 | J372: =IFERROR(VLOOKUP(Table35[[#This Row],[R&D Tags]],H:H,1,FALSE), " ")
B373: 2-076-PI030_01-X | H373: 2-504-PI003-X | J373: =IFERROR(VLOOKUP(Table35[[#This Row],[R&D Tags]],H:H,1,FALSE), " ")
B374: 2-076-PI061_01-X | H374: 2-604-ANTRIEB31-KW | J374: =IFERROR(VLOOKUP(Table35[[#This Row],[R&D Tags]],H:H,1,FALSE), " ")
B375: 2-076-QI050_01 | H375: 2-604-ANTRIEB32-KW | J375: =IFERROR(VLOOKUP(Table35[[#This Row],[R&D Tags]],H:H,1,FALSE), " ")
B376: 2-076-SCHNECKEN-X | H376: 2-604-ANTRIEB33-KW | J376: =IFERROR(VLOOKUP(Table35[[#This Row],[R&D Tags]],H:H,1,FALSE), " ")
...

Sheet Old List of R&D Tags vs IDI
A1: Tags | B1: Sensor/Calculation Tag | H1: IDI Tags | I1: R&D Tags | J1: DOES R&D = IDI?
A2: 1-000-A001_35-X | B2: 1-000-A001_37-X | H2: 1-000-FI005_10-X | I2: QMS11_SCN1QM1-X | J2: =IFERROR(VLOOKUP(Table358[[#This Row],[R&D Tags]],'Old List of R&D Tags vs IDI'!H:H,1,FALSE), " ") -> QMS11_SCN1QM1-X
A3: 1-000-A001_36-X | B3: 1-000-A001_38-X | H3: 2-199-PI068-X | I3: QMS11_MIC_MSTSCN2-X1 | J3: =IFERROR(VLOOKUP(Table358[[#This Row],[R&D Tags]],'Old List of R&D Tags vs IDI'!H:H,1,FALSE), " ") -> QMS11_MIC_MSTSCN2-X1 | L3: 284 R&D tags match IDI
A4: 1-000-A001_37-X | B4: 1-000-A004_3-X | H4: Fixative 1 expected usage * Production rate [t/h] + Fixative 2 expected usage * Production rate [t/h] | I4: QMS11_2-303-NC071-X | J4: =IFERROR(VLOOKUP(Table358[[#This Row],[R&D Tags]],'Old List of R&D Tags vs IDI'!H:H,1,FALSE), " ") -> QMS11_2-303-NC071-X | L4: 65 R&D Tags are not in the IDI
A5: 1-000-A004_3-X | B5: 1-000-A005_10-WG | H5: If total bentonite consumption rate (reconciled) < 80, set value = 0 | I5: QMS11_2-238-NC071-X | J5: =IFERROR(VLOOKUP(Table358[[#This Row],[R&D Tags]],'Old List of R&D Tags vs IDI'!H:H,1,FALSE), " ") -> QMS11_2-238-NC071-X
A6: 1-000-A005_11-X | B6: 1-000-A005_11-WG | H6: GMC_A1_46_0.7KV-RSM2-RUECK | I6: QMS11_2-203-NC071-X | J6: =IFERROR(VLOOKUP(Table358[[#This Row],[R&D Tags]],'Old List of R&D Tags vs IDI'!H:H,1,FALSE), " ") -> QMS11_2-203-NC071-X
A7: 1-000-CC001_1-X | B7: 1-000-A005_11-X | H7: QLS-REEL-TURNUP | I7: QMS11_2-138-NC071-X | J7: =IFERROR(VLOOKUP(Table358[[#This Row],[R&D Tags]],'Old List of R&D Tags vs IDI'!H:H,1,FALSE), " ") -> QMS11_2-138-NC071-X
A8: 1-000-CC005_1_1-X | B8: 1-000-A005_15-WG | H8: 2-604-ANTRIEB33-KW | I8: QMS11_2-103-NC071-X | J8: =IFERROR(VLOOKUP(Table358[[#This Row],[R&D Tags]],'Old List of R&D Tags vs IDI'!H:H,1,FALSE), " ") -> QMS11_2-103-NC071-X
A9: 1-000-CC005_1_2-X | B9: 1-000-A005_15-X | H9: 1-000-PI001_30-X | I9: QMS11_2-044-V511-N_FU | J9: =IFERROR(VLOOKUP(Table358[[#This Row],[R&D Tags]],'Old List of R&D Tags vs IDI'!H:H,1,FALSE), " ") -> QMS11_2-044-V511-N_FU
A10: 1-000-CC005_1_3-X | B10: 1-000-A005_40-N | H10: 1-000-PI004_1_2-X | I10: QMS11_2-044-V411-N_FU | J10: =IFERROR(VLOOKUP(Table358[[#This Row],[R&D Tags]],'Old List of R&D Tags vs IDI'!H:H,1,FALSE), " ") -> QMS11_2-044-V411-N_FU
A11: 1-000-CC006_01-X | B11: 1-000-A005_9-WG | H11: 2-304-ANTRIEB15-KW | I11: QMS11_2-044-V311-N_FU | J11: =IFERROR(VLOOKUP(Table358[[#This Row],[R&D Tags]],'Old List of R&D Tags vs IDI'!H:H,1,FALSE), " ") -> QMS11_2-044-V311-N_FU
A12: 1-000-CC007_01-X | B12: 1-000-CC001_30-X | H12: 2-238-UZ020-915 | I12: QMS11_2-044-V211-N_FU | J12: =IFERROR(VLOOKUP(Table358[[#This Row],[R&D Tags]],'Old List of R&D Tags vs IDI'!H:H,1,FALSE), " ") -> QMS11_2-044-V211-N_FU
A13: 1-000-EI002_1-X | B13: 1-000-CC002_1-X | H13: 2-204-ANTRIEB13-KW | I13: QMS11_2-044-V111-N1 | J13: =IFERROR(VLOOKUP(Table358[[#This Row],[R&D Tags]],'Old List of R&D Tags vs IDI'!H:H,1,FALSE), " ") -> QMS11_2-044-V111-N1
A14: 1-000-EI004_1-X | B14: 1-000-CC005_1_1-X | H14: 1-000-PC004_3_2-X | I14: QMS11_2-044-MC433-X | J14: =IFERROR(VLOOKUP(Table358[[#This Row],[R&D Tags]],'Old List of R&D Tags vs IDI'!H:H,1,FALSE), " ") -> QMS11_2-044-MC433-X
A15: 1-000-EI004_2-X | B15: 1-000-CC005_1_2-X | H15: 2-246-YP043-D6 | I15: QMS11_2-044-MC333-W | J15: =IFERROR(VLOOKUP(Table358[[#This Row],[R&D Tags]],'Old List of R&D Tags vs IDI'!H:H,1,FALSE), " ") -> QMS11_2-044-MC333-W
A16: 1-000-EI005_10-X | B16: 1-000-CC005_1_3-X | H16: 1-000-FC005_4-X | I16: QMS11_2-008-QC041.05.01-X | J16: =IFERROR(VLOOKUP(Table358[[#This Row],[R&D Tags]],'Old List of R&D Tags vs IDI'!H:H,1,FALSE), " ") -> QMS11_2-008-QC041.05.01-X
... A337: QMS11_2-009-FI200.01.2-X | B337: 2-060-YP052_01-X | H337: 2-008-FI080_03_3-X | I337: 2-009-PI806_01-X | J337: =IFERROR(VLOOKUP(Table358[[#This Row],[R&D Tags]],'Old List of R&D Tags vs IDI'!H:H,1,FALSE), " ")
A338: QMS11_2-009-FI200.01.4-X | B338: 2-060-YP052_02-X | H338: 2-008-FI080_03_4-X | J338: =IFERROR(VLOOKUP(Table358[[#This Row],[R&D Tags]],'Old List of R&D Tags vs IDI'!H:H,1,FALSE), " ")
A339: QMS11_2-009-FI200.01.5-X | B339: 2-076-AW1 | H339: PM1_ABRISS-ERKENNUNG | J339: =IFERROR(VLOOKUP(Table358[[#This Row],[R&D Tags]],'Old List of R&D Tags vs IDI'!H:H,1,FALSE), " ")
A340: QMS11_2-009-FI200.01.7-X | B340: 2-076-AW2 | H340: QO-REEL-ID-CUR-CALC | J340: =IFERROR(VLOOKUP(Table358[[#This Row],[R&D Tags]],'Old List of R&D Tags vs IDI'!H:H,1,FALSE), " ")
A341: QMS11_2-009-FI208.01-X | B341: 2-076-AW3 | H341: 1-000-CC001_30-X | I341: QO_TSI_MD | J341: =IFERROR(VLOOKUP(Table358[[#This Row],[R&D Tags]],'Old List of R&D Tags vs IDI'!H:H,1,FALSE), " ")
A342: QMS11_2-009-FI210.01-X | B342: 2-076-FC011_01 | H342: 1-000-EI003_1-X | I342: QO_CMT | J342: =IFERROR(VLOOKUP(Table358[[#This Row],[R&D Tags]],'Old List of R&D Tags vs IDI'!H:H,1,FALSE), " ")
A343: QMS11_2-044-MC333-W | B343: 2-076-FC011_01-X | H343: 2-008-QI041_11-X | I343: 2-076-LC011_01-X | J343: =IFERROR(VLOOKUP(Table358[[#This Row],[R&D Tags]],'Old List of R&D Tags vs IDI'!H:H,1,FALSE), " ")
A344: QMS11_2-044-MC433-X | B344: 2-076-FC011_02 | H344: 2-008-CI033_01-X | I344: 1-000-FC005_11-X | J344: =IFERROR(VLOOKUP(Table358[[#This Row],[R&D Tags]],'Old List of R&D Tags vs IDI'!H:H,1,FALSE), " ")
A345: QMS11_2-044-V111-N1 | B345: 2-076-FC011_02-X | H345: 2-008-FC031_01-X | I345: 1-000-FC005_13-X | J345: =IFERROR(VLOOKUP(Table358[[#This Row],[R&D Tags]],'Old List of R&D Tags vs IDI'!H:H,1,FALSE), " ")
A346: QMS11_2-044-V211-N_FU | B346: 2-076-FC015_01 | H346: 2-008-FC031_02-X | I346: QMS11_2-009-FI200.01.4-X | J346: =IFERROR(VLOOKUP(Table358[[#This Row],[R&D Tags]],'Old List of R&D Tags vs IDI'!H:H,1,FALSE), " ")
A347: QMS11_2-044-V311-N_FU | B347: 2-076-FC015_01 | H347: 2-008-FC031_02-X | I347: QMS11_2-009-FI200.01.7-X | J347: =IFERROR(VLOOKUP(Table358[[#This Row],[R&D Tags]],'Old List of R&D Tags vs IDI'!H:H,1,FALSE), " ")
A348: QMS11_2-044-V411-N_FU | B348: 2-076-FC015_01-X | H348: 2-008-FC031_02-X | I348: QMS11_2-009-FI210.01-X | J348: =IFERROR(VLOOKUP(Table358[[#This Row],[R&D Tags]],'Old List of R&D Tags vs IDI'!H:H,1,FALSE), " ")
A349: QMS11_2-044-V511-N_FU | B349: 2-076-FC021_01 | H349: 2-008-FC031_04-X | I349: QMS11_2-009-FI208.01-X | J349: =IFERROR(VLOOKUP(Table358[[#This Row],[R&D Tags]],'Old List of R&D Tags vs IDI'!H:H,1,FALSE), " ")
A350: QMS11_2-103-NC071-X | B350: 2-076-FC021_01-X | H350: 2-008-FC080_01_2-X | I350: 2-009-PI200_01_3-X | J350: =IFERROR(VLOOKUP(Table358[[#This Row],[R&D Tags]],'Old List of R&D Tags vs IDI'!H:H,1,FALSE), " ")
A351: QMS11_2-138-NC071-X | B351: 2-076-FC021_02 | H351: 2-008-FC087_01-X | I351: 2-008-FI807_01-X | J351: =IFERROR(VLOOKUP(Table358[[#This Row],[R&D Tags]],'Old List of R&D Tags vs IDI'!H:H,1,FALSE), " ")
A352: QMS11_2-203-NC071-X | B352: 2-076-FC021_02-X | H352: 2-008-FC088-X | I352: 2-008-FI807_03-X | J352: =IFERROR(VLOOKUP(Table358[[#This Row],[R&D Tags]],'Old List of R&D Tags vs IDI'!H:H,1,FALSE), " ")
A353: QMS11_2-238-NC071-X | B353: 2-076-FC025_01 | H353: 2-008-FI033_01-X | I353: 2-008-FI807_06-X | J353: =IFERROR(VLOOKUP(Table358[[#This Row],[R&D Tags]],'Old List of R&D Tags vs IDI'!H:H,1,FALSE), " ")
A354: QMS11_2-303-NC071-X | B354: 2-076-FC025_01-X | H354: 2-008-FI087_11-X | J354: =IFERROR(VLOOKUP(Table358[[#This Row],[R&D Tags]],'Old List of R&D Tags vs IDI'!H:H,1,FALSE), " ")
A355: QMS11_MIC_MSTSCN1-X1 | B355: 2-076-FC030_01-X | H355: 2-008-FI087_21-X | J355: =IFERROR(VLOOKUP(Table358[[#This Row],[R&D Tags]],'Old List of R&D Tags vs IDI'!H:H,1,FALSE), " ")
A356: QMS11_MIC_MSTSCN2-X1 | B356: 2-076-FC050_01-X | H356: 2-008-FI087_22-X | J356: =IFERROR(VLOOKUP(Table358[[#This Row],[R&D Tags]],'Old List of R&D Tags vs IDI'!H:H,1,FALSE), " ")
A357: QMS11_SCN1QM1-X | B357: 2-076-FC061_01 | H357: 2-008-FI087_23-X | J357: =IFERROR(VLOOKUP(Table358[[#This Row],[R&D Tags]],'Old List of R&D Tags vs IDI'!H:H,1,FALSE), " ")
A358: QO_BERSTWIDERSTAND | B358: 2-076-FC061_01-X | H358: 2-008-FI087_24-X | J358: =IFERROR(VLOOKUP(Table358[[#This Row],[R&D Tags]],'Old List of R&D Tags vs IDI'!H:H,1,FALSE), " ")
A359: QO_CMT | B359: 2-076-FC061_02 | H359: 2-008-HC041_10_1-Y | J359: =IFERROR(VLOOKUP(Table358[[#This Row],[R&D Tags]],'Old List of R&D Tags vs IDI'!H:H,1,FALSE), " ")
A360: QO_SCT_CD | B360: 2-076-FC061_02-X | H360: 2-008-HC041_30_1-Y | J360: =IFERROR(VLOOKUP(Table358[[#This Row],[R&D Tags]],'Old List of R&D Tags vs IDI'!H:H,1,FALSE), " ")
...

Sheet CHECK THIS ONE
B1: IDI | C1: TAGS NEW R&D | D1: IS R&D Tag in IDI? | F1: 588 IDI tags & calcs
B2: 1-000-FI005_10-X | C2: QO-REEL-ID-CUR-CALC | D2: =IFERROR(VLOOKUP(Table2[[#This Row],[TAGS NEW R&D]],B:B,1,FALSE), " ") -> QO-REEL-ID-CUR-CALC | F2: 300 R&D Tags in IDI
B3: 2-246-YP043-D6 | C3: QMS11_SCN1QM1-X | D3: =IFERROR(VLOOKUP(Table2[[#This Row],[TAGS NEW R&D]],B:B,1,FALSE), " ") -> QMS11_SCN1QM1-X | F3: 366 tags R&D
B4: 2-199-P071_2-X | C4: QMS11_MIC_MSTSCN2-X1 | D4: =IFERROR(VLOOKUP(Table2[[#This Row],[TAGS NEW R&D]],B:B,1,FALSE), " ") -> QMS11_MIC_MSTSCN2-X1 | F4: 66 tags not in IDI
B5: 1-000-EI002_1-X | C5: QMS11_2-303-NC071-X | D5: =IFERROR(VLOOKUP(Table2[[#This Row],[TAGS NEW R&D]],B:B,1,FALSE), " ") -> QMS11_2-303-NC071-X
B6: 1-000-FC028_02-X | C6: QMS11_2-238-NC071-X | D6: =IFERROR(VLOOKUP(Table2[[#This Row],[TAGS NEW R&D]],B:B,1,FALSE), " ") -> QMS11_2-238-NC071-X
B7: 1-000-CC007_01-X | C7: QMS11_2-203-NC071-X | D7: =IFERROR(VLOOKUP(Table2[[#This Row],[TAGS NEW R&D]],B:B,1,FALSE), " ") -> QMS11_2-203-NC071-X
B8: 2-000-2A1J23-P | C8: QMS11_2-138-NC071-X | D8: =IFERROR(VLOOKUP(Table2[[#This Row],[TAGS NEW R&D]],B:B,1,FALSE), " ") -> QMS11_2-138-NC071-X
B9: Total dry strength agent consumption rate * 0.9768 + 25939/(24*30) | C9: QMS11_2-103-NC071-X | D9: =IFERROR(VLOOKUP(Table2[[#This Row],[TAGS NEW R&D]],B:B,1,FALSE), " ") -> QMS11_2-103-NC071-X
B10: 2-033-FC150-X | C10: QMS11_2-044-V511-N_FU | D10: =IFERROR(VLOOKUP(Table2[[#This Row],[TAGS NEW R&D]],B:B,1,FALSE), " ") -> QMS11_2-044-V511-N_FU
B11: 2-009-PC200_11 | C11: QMS11_2-044-V411-N_FU | D11: =IFERROR(VLOOKUP(Table2[[#This Row],[TAGS NEW R&D]],B:B,1,FALSE), " ") -> QMS11_2-044-V411-N_FU
B12: 1-000-FC005_8_2-X | C12: QMS11_2-044-V311-N_FU | D12: =IFERROR(VLOOKUP(Table2[[#This Row],[TAGS NEW R&D]],B:B,1,FALSE), " ") -> QMS11_2-044-V311-N_FU
B13: 1-000-FC005_3-X | C13: QMS11_2-044-V211-N_FU | D13: =IFERROR(VLOOKUP(Table2[[#This Row],[TAGS NEW R&D]],B:B,1,FALSE), " ") -> QMS11_2-044-V211-N_FU
B14: 1-000-CC006_01-X | C14: QMS11_2-044-V111-N1 | D14: =IFERROR(VLOOKUP(Table2[[#This Row],[TAGS NEW R&D]],B:B,1,FALSE), " ") -> QMS11_2-044-V111-N1
B15: 2-009-FI210_01-X | C15: QMS11_2-044-MC433-X | D15: =IFERROR(VLOOKUP(Table2[[#This Row],[TAGS NEW R&D]],B:B,1,FALSE), " ") -> QMS11_2-044-MC433-X
B16: Total sizing agent consumption rate * 0.8642 + 11273/(24*30) | C16: QMS11_2-044-MC333-W | D16: =IFERROR(VLOOKUP(Table2[[#This Row],[TAGS NEW R&D]],B:B,1,FALSE), " ") -> QMS11_2-044-MC333-W
... B367: 2-008-PC088-X | C367: 2-009-PI806_01-X | D367: =IFERROR(VLOOKUP(Table2[[#This Row],[TAGS NEW R&D]],B:B,1,FALSE), " ")
B368: 2-008-PD080_10_1-X | D368: =IFERROR(VLOOKUP(Table2[[#This Row],[TAGS NEW R&D]],B:B,1,FALSE), " ")
B369: 2-008-PD083_01-X | D369: =IFERROR(VLOOKUP(Table2[[#This Row],[TAGS NEW R&D]],B:B,1,FALSE), " ")
B370: 2-008-PD087_01-X | D370: =IFERROR(VLOOKUP(Table2[[#This Row],[TAGS NEW R&D]],B:B,1,FALSE), " ")
B371: 2-008-PD087_11-X | D371: =IFERROR(VLOOKUP(Table2[[#This Row],[TAGS NEW R&D]],B:B,1,FALSE), " ")
B372: 2-008-PD087_21-X | D372: =IFERROR(VLOOKUP(Table2[[#This Row],[TAGS NEW R&D]],B:B,1,FALSE), " ")
B373: 2-008-PI041_05_1-X | D373: =IFERROR(VLOOKUP(Table2[[#This Row],[TAGS NEW R&D]],B:B,1,FALSE), " ")
B374: 2-008-PI041_12-X | D374: =IFERROR(VLOOKUP(Table2[[#This Row],[TAGS NEW R&D]],B:B,1,FALSE), " ")
B375: 2-008-PI041_25_1-X | D375: =IFERROR(VLOOKUP(Table2[[#This Row],[TAGS NEW R&D]],B:B,1,FALSE), " ")
B376: 2-008-PI087_01-X | D376: =IFERROR(VLOOKUP(Table2[[#This Row],[TAGS NEW R&D]],B:B,1,FALSE), " ")
B377: 2-008-PI087_02-X | D377: =IFERROR(VLOOKUP(Table2[[#This Row],[TAGS NEW R&D]],B:B,1,FALSE), " ")
B378: 2-008-PI087_11-X | D378: =IFERROR(VLOOKUP(Table2[[#This Row],[TAGS NEW R&D]],B:B,1,FALSE), " ")
B379: 2-008-PI087_21-X | D379: =IFERROR(VLOOKUP(Table2[[#This Row],[TAGS NEW R&D]],B:B,1,FALSE), " ")
... B589: QMS11_SCN1QM1-X | D589: =IFERROR(VLOOKUP(Table2[[#This Row],[TAGS NEW R&D]],B:B,1,FALSE), " ")

Sheet R&D tags in IDI format
A1: Geo-Location | B1: Organisation | C1: Plant | D1: Asset | E1: Asset Component | F1: Asset Sub-Component | G1: Asset Sub-Component 2 | H1: Sensor/Calculation Tag | I1: Sensor/Calculation Description | J1: Unit of Measure | K1: Sensor Attribute (TERA Cost Category) | L1: TERA COSTS? [Y/N] | M1: Comments
A2: X5P4+WW | B2: AS-00 | C2: Aschaffenburg Paper | D2: MBS | E2: Autoline | H2: QO_SCT_CD | I2: MBS SCT CD
A3: X5P4+WW | B3: AS-00 | C3: Aschaffenburg Paper | D3: MBS | E3: Autoline | H3: QO_SCT_MD | I3: MBS SCT MD
A4: X5P4+WW | B4: AS-00 | C4: Aschaffenburg Paper | D4: MBS | E4: Autoline | H4: QO_BERSTWIDERSTAND | I4: MBS Burst
A5: X5P4+WW | B5: AS-00 | C5: Aschaffenburg Paper | D5: MBS | E5: Autoline | H5: QO_CMT | I5: MBS CMT30
A6: X5P4+WW | B6: AS-00 | C6: Aschaffenburg Paper | D6: PM1 | E6: Popereel | H6: QO-REEL-WEIGHT-CUR | I6: Current reel weight | J6: Kg
A7: X5P4+WW | B7: AS-00 | C7: Aschaffenburg Paper | D7: PM1 | E7: Popereel | H7: QO-REEL-LENGTH-CUR | I7: Current reel length | J7: M
A8: X5P4+WW | B8: AS-00 | C8: Aschaffenburg Paper | D8: PM1 | E8: Popereel | H8: QMS11_MIC_MSTSCN1-X1 | I8: Actual moisture | J8: PCT
A9: X5P4+WW | B9: AS-00 | C9: Aschaffenburg Paper | D9: PM1 | E9: Popereel | H9: QLS-REEL-DRY-CUR | I9: Current reel dry average
A10: X5P4+WW | B10: AS-00 | C10: Aschaffenburg Paper | D10: PM1 | E10: Popereel | H10: PM1-BW1-RL:GFLT.SIG | I10: BSW 2 sigma
A11: X5P4+WW | B11: AS-00 | C11: Aschaffenburg Paper | D11: PM1 | E11: Popereel | H11: PM1-PM1-SP:GFLT.SIG | I11: Mois Size Press 2 sigma
A12: X5P4+WW | B12: AS-00 | C12: Aschaffenburg Paper | D12: PM1 | E12: Popereel | H12: PM1-MO1-RL:GFLT.SIG | I12: Mois 2 sigma
A13: X5P4+WW | B13: AS-00 | C13: Aschaffenburg Paper | D13: PM1 | E13: Approach Flow | F13: Polymer system | H13: 2-008-FC083.01-X | I13: Retentionsmittel Menge l/h [0..9000 l/h] | J13: l/h | M13: IN IDI is this tag 2-008-FC083_01-X
A14: X5P4+WW | B14: AS-00 | C14: Aschaffenburg Paper | D14: PM1 | E14: Approach Flow | F14: Polymer system | H14: 2-008-FIXIER-SOLL | I14: Sollwert Fixiermittelmenge [-1..50 l/h] | J14: l/h
A15: X5P4+WW | B15: AS-00 | C15: Aschaffenburg Paper | D15: PM1 | E15: Approach Flow | F15: Polymer system | H15: 2-008-FC080_02_3-X | I15: Fixiermittelmenge Trockenausschuss [0..100 l/h] | J15: l/h
A16: X5P4+WW | B16: AS-00 | C16: Aschaffenburg Paper | D16: PM1 | H16: QLS-PM1-BREAK-STATUS2 | I16: Paper break status li:PM1-OPC-DATA.F:rtup_pls (0 = false)
A17: X5P4+WW | B17: AS-00 | C17: Aschaffenburg Paper | D17: PM1 | E17: Approach Flow | F17: Polymer system | H17: 2-008-UZ080_11-PRM-X | I17: Purate Laufrückmeldung : MESSWERT [0..1 ]
A18: X5P4+WW | B18: AS-00 | C18: Aschaffenburg Paper | D18: PM1 | E18: Approach Flow | F18: Polymer system | H18: 2-008-QC041_01-X | I18: CO2-Dosierung Deculator 1 [0..60 kg/h] | J18: kg/h
A19: X5P4+WW | B19: AS-00 | C19: Aschaffenburg Paper | D19: PM1 | E19: Approach Flow | F19: Polymer system | H19: 2-008-QC041_20-X | I19: CO2-Dosierung Deculator 2 [0..60 kg/h] | J19: kg/h
A20: X5P4+WW | B20: AS-00 | C20: Aschaffenburg Paper | D20: PM1 | E20: Approach Flow | F20: Polymer system | H20: 2-008-QC031_01-X | I20: CO2-Dosierung Bio-Rückwasser [0..60 kg/h] | J20: kg/h
A21: X5P4+WW | B21: AS-00 | C21: Aschaffenburg Paper | D21: PM1 | E21: Dryer section | F21: Afterdryers | H21: QMS11_2-009-FI200.01.2-X | I21: Steam flow to AfterDryers | J21: TONNE/HR | M21: In IDI appears 2-009-FI200_01_2
A22: X5P4+WW | B22: AS-00 | C22: Aschaffenburg Paper | D22: PM1 | E22: Speedsizer | H22: STAERKE_FW | I22: Starch consumption Bottom [m³/h] | J22: m³/h
A23: X5P4+WW | B23: AS-00 | C23: Aschaffenburg Paper | D23: PM1 | E23: Speedsizer | H23: STAERKE_BW | I23: Starch consumption Top [m³/h] | J23: m³/h
A24: X5P4+WW | B24: AS-00 | C24: Aschaffenburg Paper | D24: PM1 | E24: Speedsizer | H24: 2-076-QI050_01-X | I24: Consistency starch main line | J24: %
A25: X5P4+WW | B25: AS-00 | C25: Aschaffenburg Paper | D25: PM1 | E25: Popereel | H25: QO-REEL-CURR-AVG-WEBWIDTH | I25: Aktuelle Arbeitsbreite in cm~^0 | J25: cm
A26: X5P4+WW | B26: AS-00 | C26: Aschaffenburg Paper | D26: PM1 | E26: Speedsizer | H26: 2-033-FI100-D2-X | I26: Starch Top Roll [ml/m²] | J26: ml/m²
A27: X5P4+WW | B27: AS-00 | C27: Aschaffenburg Paper | D27: PM1 | E27: Speedsizer | H27: 2-033-FI100-D1-X | I27: Starch Bottom Roll [ml/m²] | J27: ml/m²
A28: X5P4+WW | B28: AS-00 | C28: Aschaffenburg Paper | D28: PM1 | E28: Popereel | H28: QLS-REEL-MOISTURE2-CUR | I28: Current reel moisture average(SpeedSizer)
A29: X5P4+WW | B29: AS-00 | C29: Aschaffenburg Paper | D29: PM1 | E29: Starch kitchen | H29: QMS11_2-009-FI200.01.5-X | I29: Steam flow to starch kitchen | J29: t/h | M29: In IDI appears 2-009-FI200_01_5-X
A30: X5P4+WW | B30: AS-00 | C30: Aschaffenburg Paper | D30: PM1 | E30: Starch kitchen | H30: 2-076-LC011_01-X | I30: Slurry 1 level | J30: %
A31: X5P4+WW | B31: AS-00 | C31: Aschaffenburg Paper | D31: PM1 | E31: Starch kitchen | H31: 2-076-PC035_01-X | I31: Steam Pressure Inactivation | J31: bar
A32: X5P4+WW | B32: AS-00 | C32: Aschaffenburg Paper | D32: PM1 | E32: Starch kitchen | H32: 2-076-FC021_01-Y | I32: Dilution water flow slurry 2 control setting | J32: %
A33: X5P4+WW | B33: AS-00 | C33: Aschaffenburg Paper | D33: PM1 | E33: Starch kitchen | H33: 2-076-PI021_02-X | I33: Pressure cold water for slurry mixing | J33: bar
A34: X5P4+WW | B34: AS-00 | C34: Aschaffenburg Paper | D34: PM1 | E34: Starch kitchen | H34: 2-076-FC011_01-Y | I34: Dilution water flow slurry 1 control setting | J34: %
A35: X5P4+WW | B35: AS-00 | C35: Aschaffenburg Paper | D35: PM1 | E35: Starch kitchen | H35: 2-076-FC021_02-Y | I35: Revolution of Slurry 2 to reactor (control setting) | J35: %
A36: X5P4+WW | B36: AS-00 | C36: Aschaffenburg Paper | D36: PM1 | E36: Starch kitchen | H36: 2-076-FC061_02-Y | I36: Revolution of Slurry 3 to reactor (control setting) | J36: %
A37: X5P4+WW | B37: AS-00 | C37: Aschaffenburg Paper | D37: PM1 | E37: Starch kitchen | H37: 2-076-FC011_02-Y | I37: Revolution of Slurry 1 to reactor (control setting) | J37: %
A38: X5P4+WW | B38: AS-00 | C38: Aschaffenburg Paper | D38: PM1 | E38: Starch kitchen | H38: 2-076-PI040_01-X | I38: Pressure in cyclon storage tank | J38: bar
A39: X5P4+WW | B39: AS-00 | C39: Aschaffenburg Paper | D39: PM1 | E39: Dryer section | F39: Pre-Drying Group | G39: Cylinders | H39: 2-009-PD201_02-X | I39: Cylinder 2 differential pressure | J39: bar | M39: in IDI corrected Tag
A40: X5P4+WW | B40: AS-00 | C40: Aschaffenburg Paper | D40: PM1 | E40: Dryer section | F40: Pre-Drying Group | H40: 2-104-NC010-X | I40: PD1 Fabric tension
...

Sheet R&D Tags Missing in IDI (AB)
A1: Column1 | B1: TAGS | C1: tag corrected | D1: TAG DESC/NAME | E1: TAG DESC/NAME ENGLISH TRANSLATION/STANDARDISATION IF NEEDED | F1: UNITS | G1: ASSET | H1: Asset Component | I1: Asset Sub-Component
B2: QO_SCT_CD | D2: MBS SCT CD | E2: MBS SCT CD | G2: MBS | H2: Autoline
B3: QO_SCT_MD | D3: MBS SCT MD | E3: MBS SCT MD | G3: MBS | H3: Autoline | K3: 66 tags R&D want adding to IDI
B4: QO_BERSTWIDERSTAND | D4: MBS Burst | E4: MBS Burst | G4: MBS | H4: Autoline
B5: QO_CMT | D5: MBS CMT30 | E5: MBS CMT30 | G5: MBS | H5: Autoline
B6: QO-REEL-WEIGHT-CUR | D6: Current reel weight | E6: Current reel weight | F6: Kg | G6: PM1 | H6: Popereel
B7: QO-REEL-LENGTH-CUR | D7: Current reel length | E7: Current reel length | F7: M | G7: PM1 | H7: Popereel
B8: QMS11_MIC_MSTSCN1-X1 | D8: Actual moisture | E8: Actual moisture | F8: PCT | G8: PM1 | H8: Popereel
B9: QLS-REEL-DRY-CUR | D9: Current reel dry average | E9: Current reel dry average | G9: PM1 | H9: Popereel
B10: PM1-BW1-RL:GFLT.SIG | D10: BSW 2 sigma | E10: BSW 2 sigma | G10: PM1 | H10: Popereel
B11: PM1-PM1-SP:GFLT.SIG | D11: Mois Size Press 2 sigma | E11: Mois Size Press 2 sigma | G11: PM1 | H11: Popereel
B12: PM1-MO1-RL:GFLT.SIG | D12: Mois 2 sigma | E12: Mois 2 sigma | G12: PM1 | H12: Popereel
B13: 2-008-FC083.01-X | C13: IN IDI is this tag 2-008-FC083_01-X | D13: Retentionsmittel Menge l/h [0..9000 l/h] | E13: Retention agent quantity | F13: l/h | G13: PM1 | H13: Approach Flow | I13: Polymer system
B14: 2-008-FIXIER-SOLL | D14: Sollwert Fixiermittelmenge [-1..50 l/h] | E14: Fixative Setpoint | F14: l/h | G14: PM1 | H14: Approach Flow | I14: Polymer system
B15: 2-008-FC080_02_3-X | D15: Fixiermittelmenge Trockenausschuss [0..100 l/h] | E15: Fixative Dry Waste | F15: l/h | G15: PM1 | H15: Approach Flow | I15: Polymer system
B16: 2-033-FI200-G_M2 | D16: Starch uptake by paper Top Roll [g/m2] | E16: Starch uptake by paper Top Roll | F16: g/m² | G16: PM1 | H16: Speedsizer
B17: QLS-PM1-BREAK-STATUS2 | D17: Paper break status li:PM1-OPC-DATA.F:rtup_pls (0 = false) | E17: Paper break status | G17: PM1
B18: 2-008-UZ080_11-PRM-X | D18: Purate Laufrückmeldung : MESSWERT [0..1 ] | E18: Purate Running Feedback (Measured Value) | G18: PM1 | H18: Approach Flow | I18: Polymer system
B19: 2-008-QC041_01-X | D19: CO2-Dosierung Deculator 1 [0..60 kg/h] | E19: CO2 Dosage Deculator 1 | F19: kg/h | G19: PM1 | H19: Approach Flow | I19: Polymer system
B20: 2-008-QC041_20-X | D20: CO2-Dosierung Deculator 2 [0..60 kg/h] | E20: CO2 Dosage Deculator 2 | F20: kg/h | G20: PM1 | H20: Approach Flow | I20: Polymer system
B21: 2-008-QC031_01-X | D21: CO2-Dosierung Bio-Rückwasser [0..60 kg/h] | E21: CO2 dosage bio-backwater | F21: kg/h | G21: PM1 | H21: Approach Flow | I21: Polymer system
B22: QMS11_2-009-FI200.01.2-X | C22: In IDI appears 2-009-FI200_01_2 | D22: Steam flow to AfterDryers | E22: Steam flow to After Dryers | F22: TONNE/HR | G22: PM1 | H22: Dryer section | I22: Afterdryers
B23: STAERKE_FW | D23: Starch consumption Bottom [m³/h] | E23: Starch consumption Bottom | F23: m³/h | G23: PM1 | H23: Speedsizer
B24: STAERKE_BW | D24: Starch consumption Top [m³/h] | E24: Starch consumption Top | F24: m³/h | G24: PM1 | H24: Speedsizer
B25: 2-076-QI050_01-X | D25: Consistency starch main line | E25: Consistency starch main line | F25: % | G25: PM1 | H25: Speedsizer
B26: QO-REEL-CURR-AVG-WEBWIDTH | D26: Aktuelle Arbeitsbreite in cm~^0 | E26: Current working width | F26: cm | G26: PM1 | H26: Popereel
B27: 2-033-FI100-D2-X | D27: Starch Top Roll [ml/m²] | E27: Starch Top Roll | F27: ml/m² | G27: PM1 | H27: Speedsizer
B28: 2-033-FI100-D1-X | D28: Starch Bottom Roll [ml/m²] | E28: Starch Bottom Roll | F28: ml/m² | G28: PM1 | H28: Speedsizer
B29: QLS-REEL-MOISTURE2-CUR | D29: Current reel moisture average(SpeedSizer) | E29: Current reel moisture average (SpeedSizer) | G29: PM1 | H29: Popereel
B30: QMS11_2-009-FI200.01.5-X | C30: In IDI appears 2-009-FI200_01_5-X | D30: Steam flow to starch kitchen | E30: Steam flow to starch kitchen | F30: t/h | G30: PM1 | H30: Starch kitchen
B31: 2-076-LC011_01-X | D31: Slurry 1 level | E31: Slurry 1 level | F31: % | G31: PM1 | H31: Starch kitchen
B32: 2-076-PC035_01-X | D32: Steam Pressure Inactivation | E32: Steam Pressure Inactivation | F32: bar | G32: PM1 | H32: Starch kitchen
B33: 2-076-FC021_01-Y | D33: Dilution water flow slurry 2 control setting | E33: Dilution water flow slurry 2 control setting | F33: % | G33: PM1 | H33: Starch kitchen
B34: 2-076-PI021_02-X | D34: Pressure cold water for slurry mixing | E34: Pressure cold water for slurry mixing | F34: bar | G34: PM1 | H34: Starch kitchen
B35: 2-076-FC011_01-Y | D35: Dilution water flow slurry 1 control setting | E35: Dilution water flow slurry 1 control setting | F35: % | G35: PM1 | H35: Starch kitchen
B36: 2-076-FC021_02-Y | D36: Revolution of Slurry 2 to reactor (control setting) | E36: Revolution of Slurry 2 to reactor (control setting) | F36: % | G36: PM1 | H36: Starch kitchen
B37: 2-076-FC061_02-Y | D37: Revolution of Slurry 3 to reactor (control setting) | E37: Revolution of Slurry 3 to reactor (control setting) | F37: % | G37: PM1 | H37: Starch kitchen
B38: 2-076-FC011_02-Y | D38: Revolution of Slurry 1 to reactor (control setting) | E38: Revolution of Slurry 1 to reactor (control setting) | F38: % | G38: PM1 | H38: Starch kitchen
B39: 2-076-PI040_01-X | D39: Pressure in cyclon storage tank | E39: Pressure in cyclon storage tank | F39: bar | G39: PM1 | H39: Starch kitchen
B40: 2-009-PD201_02-X | C40: in IDI corrected Tag | D40: Cylinder 2 differential pressure | E40: Cylinder 2 differential pressure | F40: bar
...

Sheet IDI tags corrected
A2: Geo-Location | B2: Organisation | C2: Plant | D2: Asset | E2: Asset Component | F2: Asset Sub-Component | G2: Asset Sub-Component 2 | H2: Sensor/Calculation Tag in IDI | I2: Correct Naming of Tag! | J2: Sensor/Calculation Description | K2: Unit of Measure | L2: Sensor Attribute (TERA Cost Category) | M2: TERA COSTS? [Y/N]
A3: X5P4+WW | B3: AS-00 | C3: Aschaffenburg Paper | D3: Stock Preparation | E3: Pulper | H3: 1-000-CC001_30-X | I3: 1-000-CC001_1-X | J3: Pulper consistency | K3: %
A4: X5P4+WW | B4: AS-00 | C4: Aschaffenburg Paper | D4: PM1 | E4: Dryer section | F4: Pre-Drying Group | G4: Cylinders | H4: 2-009-PC201_02-X | I4: 2-009-PD201_02-X | J4: Cylinder 2 differential pressure | K4: bar
A5: X5P4+WW | B5: AS-00 | C5: Aschaffenburg Paper | D5: PM1 | F5: Press Section | G5: Steambox | H5: FI092.01 | I5: 2-009-FI208.01-X | J5: Steam to steambox | K5: t/h | L5: Thermal | M5: Y
A6: X5P4+WW | B6: AS-00 | C6: Aschaffenburg Paper | D6: PM1 | H6: 2-009-FI200_01_7 | I6: 2-009-FI200_01_7-X | J6: Steam to machine hall heating | K6: t/h | L6: Thermal | M6: Y
D9: ** Updated in "KM, AB, ZN, WH IDI - UPDATED" see them in yellow on this document!

Sheet Sheet5

Sheet Sheet4
C3: QO-REEL-ID-CUR-CALC
C4: GRADE_NAME
C5: QO_SCT_CD
C6: QO_SCT_MD
C7: QO_BERSTWIDERSTAND
C8: QO_CMT
C9: 2-008-P041_10-XI
C10: PM1_ABRISS-ERKENNUNG
C11: 2-008-VPOPE-AR0
C12: QO-REEL-WEIGHT-CUR
C13: QLS-REEL-WIDTH-CUR
C14: QO-REEL-LENGTH-CUR
... C368: 2-009-PI806_01-X
