Workbook

Sheet Summary
B2: GOLDEN BATCH SUB FOLDER | C2: REQUESTED LOOPS | D2: AVAILABLE / IMPLEMENTED | E2: % PROGRESS | F2: COMMENTS
B3: TOTAL | C3: =SUM(C4:C33) -> 743 | D3: =SUM(D4:D33) -> 144 | E3: =D3/C3 -> 0.19380888
B4: Main KPIs | C4: ='Main KPIs'!$B$1 -> 47 | D4: ='Main KPIs'!$D$1 -> 18 | E4: =D4/C4 -> 0.38297872
B5: Paper Quality | C5: ='Paper Quality'!$B$1 -> 38 | D5: ='Paper Quality'!$D$1 -> 20 | E5: =D5/C5 -> 0.52631579
B6: Stock prep main KPI | C6: ='Stock prep main KPI'!$B$1 -> 25 | D6: ='Stock prep main KPI'!$D$1 -> 18 | E6: =D6/C6 -> 0.72
B7: Approach Flow - Thick Stock | C7: ='Approach Flow - Thick Stock'!$B$1 -> 47 | D7: ='Approach Flow - Thick Stock'!$D$1 -> 38 | E7: =D7/C7 -> 0.80851064
B8: Approach Flow - Thinstock | C8: ='Approach Flow - Thinstock'!$B$1 -> 57 | D8: ='Approach Flow - Thinstock'!$D$1 -> 4 | E8: =D8/C8 -> 0.070175439
B9: Headbox | C9: =Headbox!$B$1 -> 29 | D9: =Headbox!$D$1 -> 10 | E9: =D9/C9 -> 0.34482759
B10: Forming section | C10: ='Forming section'!$B$1 -> 43 | D10: ='Forming section'!$D$1 -> 1 | E10: =D10/C10 -> 0.023255814
B11: Press | C11: =Press!$B$1 -> 72 | D11: =Press!$D$1 -> 6 | E11: =D11/C11 -> 0.083333333
B12: Drying section | C12: ='Drying section'!$B$1 -> 46 | D12: ='Drying section'!$D$1 -> 0 | E12: =D12/C12 -> 0
B13: Ventilation - PD | C13: ='Ventilation - PD'!$B$1 -> 7 | D13: ='Ventilation - PD'!$D$1 -> 0 | E13: =D13/C13 -> 0
B14: Ventilation - AD | C14: ='Ventilation - AD'!$B$1 -> 7 | D14: ='Ventilation - AD'!$D$1 -> 0 | E14: =D14/C14 -> 0
B15: Sizer | C15: =Sizer!$B$1 -> 27 | D15: =Sizer!$D$1 -> 0 | E15: =D15/C15 -> 0
B16: Pope Reeler | C16: ='Pope Reeler'!$B$1 -> 10 | D16: ='Pope Reeler'!$D$1 -> 0 | E16: =D16/C16 -> 0
B17: Draws and Drives | C17: ='Draws and Drives'!$B$1 -> 46 | D17: ='Draws and Drives'!$D$1 -> 3 | E17: =D17/C17 -> 0.065217391
B18: Steam consumption | C18: ='Steam consumption'!$B$1 -> 21 | D18: ='Steam consumption'!$D$1 -> 9 | E18: =D18/C18 -> 0.42857143
B19: Steam | C19: =Steam!$B$1 -> 117 | D19: =Steam!$D$1 -> 1 | E19: =D19/C19 -> 0.0085470085
B20: Starch | C20: =Starch!$B$1 -> 53 | D20: =Starch!$D$1 -> 0 | E20: =D20/C20 -> 0
B21: Chemicals - ret. aid | C21: ='Chemicals - ret. aid'!$B$1 -> 15 | D21: ='Chemicals - ret. aid'!$D$1 -> 0 | E21: =D21/C21 -> 0
B22: Chemicals - size | C22: ='Chemicals - size'!$B$1 -> 6 | D22: ='Chemicals - size'!$D$1 -> 0 | E22: =D22/C22 -> 0
B23: Chemicals - dye | C23: ='Chemicals - dye'!$B$1 -> 14 | D23: ='Chemicals - dye'!$D$1 -> 3 | E23: =D23/C23 -> 0.21428571
B24: Fresh water consumption | F24: Not requested
B25: White water | F25: Not requested
B26: PM Discfilter | C26: ='PM Discfilter'!$B$1 -> 16 | D26: ='PM Discfilter'!$D$1 -> 13 | E26: =D26/C26 -> 0.8125
B27: Vacuum | F27: Requested, but modified soon
B28: Machine Hall ventilation | F28: Not requested
B29: Broke system | F29: Not requested
B30: Hydraulics | F30: Not requested
B31: Lubrication | F31: Not requested
B32: Compressed air | F32: Not requested

Sheet Main KPIs
B1: =COUNTA(B4:B50) -> 47 | D1: =COUNTA(D4:D50) -> 18 | F1: =D1/B1 -> 0.38297872
A3: Key parameters/Quality | B3: Loop | D3: Loop in?
A4: Production rate t/h | B4: PRODUCTION_RATE | D4: Y
A5: reel drum speed | B5: POPE_REEL_SPEED | D5: Y
A6: Paper grade | B6: CURRENT_GRADE_SPEC1 | D6: Y
A7: Grammage QCS | B7: BASSIS_WEIGHT_AVERAGE | D7: Y
A8: ODW Reeler | B8: Calculated as Basis weight minus moisture
A9: ODW Reeler COV | B9: Calculated in wedge
A10: Sizer moisture | B10: Not Available
A11: Sizer moisture COV | B11: Pending as per above
A12: Reel moisture | B12: MOISTURE_AVERAGE | D12: Y
A13: Reel moisture COV | B13: Calculated in wedge
A14: Relative steam consumption | B14: FI411 divided by gross production rate
A15: Total steam consumption | B15: FI411 | D15: Y
A16: PD relative steam consumption (press section dryness) | B16: Calculated PD divided by mass flow thick stock
A17: Vertical slice position | B17: ZQ103A01N.DACA.PV | D17: Y
A18: Horizontal slice psotion | B18: on PLC
A19: Efflux ratio - jet to wire | B19: Calculated. Ratio and delta
A20: Headbox flow | B20: CALCULATED ON WEDGE
A21: Headbox consistency | B21: Roughly calculated on wedge for evolution comparisson.
A22: Starch usage (ml/m2) | B22: N/A
A23: Starch concentration | B23: N/A
A24: Starch usage (%) | B24: N/A
A25: Starch viscosity at storage tank | B25: N/A
A26: SCT MD/CD ratio | B26: Calculated in wedge | D26: Y
A27: SCT CD | B27: SCT_CD | D27: Y
A28: CMT | B28: CMT_30 | D28: Y
A29: Burst | B29: PLESNIRE | D29: Y
A30: Color (L) | B30: CULOARE_L | D30: Y
A31: Color (a) | B31: CULOARE_a | D31: Y
A32: Color (b) | B32: CULOARE_b | D32: Y
A33: Specific dye consumption | B33: N/A
A34: WW consistency measurement | B34: N/A
A35: Specific retention aid consumption | B35: Calculated in wedge. Rough calculation.
A36: Cobb | B36: COBB_60s | D36: Y
A37: Specific sizing agent consumption | B37: Calculated in wedge. No data
A38: Air in stock | B38: N/A
A39: Specific defoamer consumption | B39: N/A
A40: Total draw | B40: Calculated in wedge. | D40: Y
A41: shoe press draw | B41: N/A
...

Sheet Paper Quality
B1: =COUNTA(B4:B45) -> 38 | D1: =COUNTA(D4:D45) -> 20 | F1: =D1/B1 -> 0.52631579
A3: Key parameters/Quality | B3: Loop | D3: Loop in?
A4: Lab temperature | B4: N/A
A5: Lab moisture | B5: N/A
A6: % of corrugated board fibre | B6: Calculated in wedge
A7: reel drum speed | B7: POPE_REEL_SPEED | D7: Y
A8: Efflux ratio - jet to wire | B8: Calculated in wedge | D8: Y
A9: Headbox consistency | B9: Calculated in wedge
A10: Starch usage (ml/m2) | B10: N/A
A11: Starch concentration | B11: N/A
A12: Grammage QCS | D12: Y
A13: Grammage lab | B13: GRAMAJ | D13: Y
A14: Grammage error | B14: Calculated in wedge | D14: Y
A15: SCT geometrical mean | B15: Calculated in wedge | D15: Y
A16: SCT MD/CD ratio | B16: Calculated in wedge | D16: Y
A17: SCT MD | B17: SCT_MD | D17: Y
A18: SCT MD index | B18: Calculated in wedge | D18: Y
A19: SCT CD | B19: SCT_CD | D19: Y
A20: SCT CD index | B20: Calculated in wedge | D20: Y
A21: Burst | B21: PLESNIRE | D21: Y
A22: Burst index | B22: Calculated in wedge | D22: Y
A23: Porosity | B23: POROSITY_GURLEY | D23: Y
A24: Plybond | B24: PLYBOND
A25: Cobb | B25: COBB_60s | D25: Y
A26: Specific sizing agent consumption | B26: Calculated in wedge
A27: Tensile strength geometrical mean | B27: Calculated in wedge | D27: Y
A28: Tensile strength MD/CD ratio | B28: Calculated in wedge | D28: Y
A29: TEA MD/CD ratio | B29: Calculated in wedge | D29: Y
A30: Tensile strength MD | B30: TENSILE_STRENGTH_MD | D30: Y
A31: Stretch MD (%) | B31: N/A
A32: TEA MD | B32: N/A
A33: Tensile strength CD | B33: TENSILE_STRENGTH_CD | D33: Y
A34: Stretch CD (%) | B34: N/A
A35: TEA CD | B35: N/A
A36: Calliper | B36: Available but no data
A37: Paper specific volume | B37: Calculated in wedge
A38: Paper density | B38: Calculated in wedge
A39: Forming section dryness TS | B39: N/A
A40: Forming section dryness DS | B40: N/A
A41: Press section dryness | B41: N/A
...

Sheet Stock prep main KPI
B1: =COUNTA(B4:B30) -> 25 | D1: =COUNTA(D4:D30) -> 18 | F1: =D1/B1 -> 0.72
A3: Key parameters/Quality | B3: Loop | D3: Loop in?
A4: Pulper recipe | B4: N/A
A5: Refiner power consumption | B5: N/A
A6: Refiner relative power consumption | B6: calculated
A7: dP across refiner | B7: calculated
A8: Production rate( STOCK PREP) | B8: WI1312013.DACA.PV | D8: Y
A9: Dump tower level | B9: LIC1317092.DACA.PV | D9: Y
A10: Fibre tower feeding the paper machine levels( C9 INLET TO FRACTIONATOR) | B10: LIC1317163.DACA.PV | D10: Y
A11: Broke storage tower level | B11: LI1437081.DACA.PV | D11: Y
A12: Paper machine whitewater level | B12: LIC1447001.DACA.PV | D12: Y
A13: Stock Prep whitewater tower level | B13: LIC1317021.DACA.PV | D13: Y
A14: Dump tower consistency | B14: QIC1317094.DACA.PV | D14: Y
A15: Dump tower consistency Set point | B15: QIC1317094.PID_PLA.SP | D15: Y
A16: Dump tower consistency output | B16: QIC1317094.PID_PLA.OP | D16: Y
A17: Dump tower consistency COV | B17: calculated
A18: Fibre tower consistency( C9 INLET TO FRACTIONATOR) | B18: QIC1317164.DACA.PV | D18: Y
A19: Fibre tower consistency Set point( C9 INLET TO FRACTIONATOR) | B19: QIC1317164.PID_PLA.SP | D19: Y
A20: Fibre tower consistency output( C9 INLET TO FRACTIONATOR) | B20: QIC1317164.PID_PLA.OP | D20: Y
A21: Fibre tower consistency( C9 INLET TO FRACTIONATOR) COV | B21: calculated
A22: Broke storage consistency measured | B22: QIC1437087.DACA.PV | D22: Y
A23: Broke storage consistency measured set point | B23: QIC1437087.PID_PLA.SP | D23: Y
A24: Broke storage consistency valve position | B24: QIC1437087.PID_PLA.OP | D24: Y
A25: Broke storage consistency measured COV | B25: calculated
A26: Paper machine whitewater consistency | B26: N/A | D26: Y
A27: Stock Prep whitewater tower consistency | B27: N/A | D27: Y
A28: Reject stream flows - coars, cleaners | B28: ? | D28: Y

Sheet Approach Flow - Thick Stock
B1: =COUNTA(B4:B50) -> 47 | D1: =COUNTA(D4:D50) -> 38 | F1: =D1/B1 -> 0.80851064
A3: Key parameters/Quality | B3: Loop | D3: Loop in?
A4: OCC storage tank level | B4: LIC1317092.DACA.PV | D4: Y
A5: OCC storage tank level set point | B5: LIC1317092.PID_PLA.SP | D5: Y
A6: OCC consistency measured | B6: QIC1317094.DACA.PV | D6: Y
A7: OCC consistency measured COV | B7: Calculated in Wedge
A8: OCC consistency set point | B8: QIC1317094.PID_PLA.SP | D8: Y
A9: OCC consistency valve position | B9: QIC1317094.PID_PLA.OP | D9: Y
A10: Broke storage tank level | B10: LI1437081.DACA.PV | D10: Y
A11: Broke storage tank level set point | B11: N/A
A12: Broke storage consistency measured | B12: QIC1437087.DACA.PV | D12: Y
A13: Broke storage consistency measured set point | B13: QIC1437087.PID_PLA.SP | D13: Y
A14: Broke storage measured COV | B14: Calculated in Wedge
A15: Broke storage consistency valve position | B15: QIC1437087.PID_PLA.OP | D15: Y
A16: Blend chest level( C 14 SF) | B16: LI1317201.DACA.PV | D16: Y
A17: Blend chest level ( C11 LF) | B17: LI1317231.DACA.PV | D17: Y
A18: Blend chest conistency( C14 SF) | B18: QIC1317202.DACA.PV | D18: Y
A19: Blend chest conistency( C14 SF) COV | B19: Calculated in Wedge
A20: Blend chest conistency set point (C14 SF) | B20: QIC1317202.PID_PLA.SP | D20: Y
A21: Blend chest consistency valve position( C14 SF) | B21: QIC1317202.PID_PLA.OP | D21: Y
A22: Blend chest conistency( C11 LF) | B22: QIC1317232.DACA.PV | D22: Y
A23: Blend chest conistency( C11 LF) COV | B23: Calculated in Wedge
A24: Blend chest conistency set point (C11 LF) | B24: QIC1317232.PID_PLA.SP | D24: Y
A25: Blend chest consistency valve position( C11 LF) | B25: QIC1317232.PID_PLA.OP | D25: Y
A26: OCC flow to blend chest( C9 TO FRACTIONATOR STAGE) | B26: FIC1317166.DACA.PV | D26: Y
A27: OCC flow to blend chest set point | B27: FIC1317166.PID_PLA.SP | D27: Y
A28: OCC flow to blend chest valve position | B28: FIC1317166.PID_PLA.OP | D28: Y
A29: Broke flow to blend chest ( TO C1) | B29: FFIC1437084.DACA.PV | D29: Y
A30: Broke flow to blend chest set point ( TO C1) | B30: FFIC1437084.PID_PLA.SP | D30: Y
A31: Broke flow to blend chest valve position (TO C1) | B31: FFIC1437084.PID_PLA.OP | D31: Y
A32: Broke flow to blend chest ( TO MACHINE CHEST) | B32: FIC1437092.DACA.PV | D32: Y
A33: Broke flow to blend chest set point ( TO MACHINE CHEST) | B33: FIC1437092.PID_PLA.SP | D33: Y
A34: Broke flow to blend chest valve position ( TO MACHINE CHEST) | B34: FIC1437092.PID_PLA.OP | D34: Y
A35: Machine chest level | B35: LIC1417001.DACA.PV | D35: Y
... A37: Machine chest conistency | B37: QIC1417018.DACA.PV | D37: Y
A38: Machine chest conistency COV | B38: Calculated in Wedge
A39: Machine chest conistency set point | B39: QIC1417018.PID_PLA.SP | D39: Y
A40: Machine chest consistency valve position | B40: QIC1417018.PID_PLA.OP | D40: Y
A41: Thickstock pump flow | B41: FIC1417005.DACA.PV | D41: Y
A42: Thickstock pump flow set point | B42: FIC1417005.PID_PLA.SP | D42: Y
...

Sheet Approach Flow - Thinstock
B1: =COUNTA(B4:B67) -> 57 | D1: =COUNTA(D4:D67) -> 4 | F1: =D1/B1 -> 0.070175439
A3: Key parameters/Quality | B3: Loop | D3: Loop in?
A4: Wire silo level | B4: LIC1417055.DACA.PV | D4: Y
A5: Wire silo level SP | B5: LIC1417055.PID_PLA.SP | D5: Y
A6: Wire silo freshwater make up valve position | B6: LIC1417055.PID_PLA_OP | D6: Y
A7: Wire solo temperature ( HB TEMP) | B7: TI_PASTA_BL | D7: Y
A8: Wire silo overflow level | B8: N/A
A9: Wire silo overflow level (valve pos.) | B9: N/A
A10: WW silo pH | B10: N/A
A11: Fan pump speed | B11: ?
A12: Fan pump speed torque | B12: ?
A14: Cleaners
A16: 1st stage 1/2 inlet pressure | B16: on wedge
A17: 1st stage 1/2 accept pressure | B17: on wedge
A18: 1st stage 1/2 reject pressure | B18: on wedge
A19: 1st stage 1/2 differential pressure | B19: on wedge
A20: 1st stage 1/2 flushing water pressure | B20: on wedge
A21: 1st stage 1/2 flushing water flow | B21: on wedge
A22: 1st stage 2/2 inlet pressure | B22: on wedge
A23: 1st stage 2/2 accept pressure | B23: on wedge
A24: 1st stage 2/2 reject pressure | B24: on wedge
A25: 1st stage 2/2 differential pressure | B25: on wedge
A26: 1st stage 2/2 flushing water pressure | B26: on wedge
A27: 1st stage 2/2 flushing water flow | B27: on wedge
... A45: 4th stage flushing water flow | B45: on wedge
A47: Screening
A49: 1st stage inlet pressure | B49: on wedge
A50: 1st stage accept pressire | B50: on wedge
A51: 1st stage differential pressure | B51: on wedge
A52: 1st stage reject flow | B52: on wedge
A53: 2nd stage inlet pressure | B53: on wedge
A54: 2nd stage accepts pressure | B54: on wedge
A55: 2nd stage differential pressure | B55: on wedge
A56: 2nd stage accepts flow | B56: on wedge
A57: 2nd stage reject flow | B57: on wedge
A58: Standpipe 1 level | B58: on wedge
A59: 3rd stage inlet pressure | B59: on wedge
A60: 3rd stage accepts pressure | B60: on wedge
... A67: Screen current | B67: N/A

Sheet Headbox
B1: =COUNTA(B4:B32) -> 29 | D1: =COUNTA(D4:D32) -> 10 | F1: =D1/B1 -> 0.34482759
A3: Key parameters/Quality | B3: Loop | D3: Loop in?
A4: Headbox consitency | B4: CALCULATED ON WEDGE
A5: Headbox flow | B5: CALCULATED ON WEDGE | D5: Y
A6: Efflux ratio - jet to wire | B6: ? | D6: Y
A7: Heabox level | B7: LIC103A04N.DACA.PV | D7: Y
A8: Heabox level set point | B8: LIC103A04N.PID_PLA.SP | D8: Y
A9: Heabox level output | B9: LIC103A04N.PID_PLA.OP | D9: Y
A10: Headbox feed pump speed | B10: ?
A11: Headbox feed pump torque | B11: ?
A12: Vertical slice position | B12: ZQ103A01N.DACA.PV | D12: Y
A13: Horizontal slice psotion | B13: ?
A14: Headbox pressure FS | B14: N/A
A15: Headbox pressure BS | B15: N/A
A16: Headbox pressure difference front to back (can be calculated on wedge) | B16: CALCULATED ON WEDGE
A17: Headbox recirculation flow | B17: N/A
A18: Headbox recirculation flow valve position | B18: HIC1417079.SP_VALUE.PV | D18: Y
A19: Headboc air supply pressure | B19: PQ103A06N.DACA.PV | D19: Y
A20: Headbox air supply pressure valve positon | B20: LCV103A09N.AUTOMANA.OP | D20: Y
A21: Headbox exhaust air valve position | B21: LCV103A04N.AUTOMANA.OP | D21: Y
A22: Headbox dilution header pressure | B22: ?
A23: Headbox stock header pressure | B23: ?
A24: Headbox headers delta pressure | B24: CALCULATED ON WEDGE
A25: Headbox dilution pressure control output | B25: ?
A26: Headbox dilution (%) | B26: ?
A27: Headbox dilution flow | B27: ?
A28: Headbox dilution recirculation valve position | B28: ?
A29: Headbox dilution recirculation flow | B29: ?
A30: Headbox temperature | B30: ?
A31: White water temperature | B31: ?
A32: Headbox and white water temperature delta | B32: ?

Sheet Forming section
B1: =COUNTA(B4:B46) -> 43 | D1: =COUNTA(D4:D46) -> 1 | F1: =D1/B1 -> 0.023255814
A3: Key parameters/Quality | B3: Loop | D3: Loop in?
A4: Bottom wire tension measured value | B4: N/A
A5: Bottom wire tension set point | B5: N/A
A6: Edge squirt pressure | B6: PIC1467026.DACA.PV | D6: Y
A7: Edge squirt pressure set point | B7: N/A
A8: Edge squirt pressure output | B8: N/A
A9: Edge squirt position FS | B9: N/A
A10: Edge squirt position BS | B10: N/A
A11: Bottom wire HP shower pressure | B11: N/A
A12: Bottom wire HP shower pressure set point | B12: N/A
A13: Bottom wire HP shower pressure output | B13: N/A
A14: Forming section exhaust fans power consumption | B14: N/A
A15: WE blowing fan temperature | B15: N/A
A16: WE blowing fan temperature - output | B16: N/A
A17: WE blowing fan power consumption | B17: N/A
A18: Wire drive relative electrical consumption (kWH/100-m/min/m-width) | B18: Calculated
... A46: Couch high vacuum output | B46: N/A

Sheet Press
B1: =COUNTA(B4:B75) -> 72 | D1: =COUNTA(D4:D75) -> 6 | F1: =D1/B1 -> 0.083333333
A3: Key parameters/Quality | B3: Loop | D3: Loop in?
A4: Dryness after press | B4: Calculated
A5: Draw wire to press | B5: N/A
A6: Draw press to shoe press | B6: N/A
A7: Pick-up felt tension | B7: N/A
A8: 1st press felt tension | B8: N/A
A9: shoe press felt tension | B9: N/A
A10: 1st press linear load Average | B10: N/A
A11: 1st press linear load FS | B11: N/A
A12: 1st press linear load FS set point | B12: N/A
A13: 1st press linear load BS | B13: N/A
A14: 1st press linear load BS set point | B14: N/A
A15: 1st press load pressure FS | B15: N/A
... A37: Shoe press felt HP pressure | B37: N/A
A38: 1st press uhle box vacuum | B38: PIC1457115.DACA.PV | D38: Y
A39: 1st press uhle box vacuum set point | B39: PIC1457115.PID_PLA.SP | D39: Y
A40: 1st press uhle box vacuum output | B40: PIC1457115.PID_PLA.OP | D40: Y
A41: Shoe press uhle box vacuum | B41: PIC1457116.DACA.PV | D41: Y
A42: Shoe press uhle box vacuum set point | B42: PIC1457116.PID_PLA.SP | D42: Y
A43: Shoe press uhle box vacuum output | B43: PIC1457116.PID_PLA.OP | D43: Y
A44: Pick up roll vacuum | B44: N/A
A45: Pick up roll vacuum set point | B45: N/A
A46: Pick up roll vacuum output | B46: N/A
A47: Pick up roll VHP shower valve position | B47: N/A
A48: Press suction roll high vacuum | B48: N/A
A49: Press suction roll high vacuum set point | B49: N/A
A50: Press suction roll high vacuum output | B50: N/A
A51: Press suction roll low vacuum | B51: N/A
A52: Press suction roll low vacuum set point | B52: N/A
A53: Press suction roll low vacuum vacuum | B53: N/A
A54: Press suction roll VHP shower valve position | B54: N/A
A55: Bottom press roll VHP shower valve position | B55: N/A
... A75: Individual press drives torques | B75: N/A

Sheet Drying section
B1: =COUNTA(B4:B75) -> 46 | D1: =COUNTA(D4:D75) -> 0 | F1: =D1/B1 -> 0
A3: Key parameters/Quality | B3: Loop | D3: Loop in?
A4: 1st dryer felt tension | B4: N/A
A5: 2nd top dryer felt tension | B5: N/A
A6: 2nd bottom dryer felt tension | B6: N/A
A7: 3rd top dryer felt tension | B7: N/A
A8: 3rd bottom dryer felt tension | B8: N/A
A9: 4th top dryer felt tension | B9: N/A
A10: 4th bottom dryer fetl tension | B10: N/A
A11: 5th top dryer felt tension | B11: N/A
A12: 5th bottom dryer felt tension | B12: N/A
A13: 6th top dryer felt tension | B13: N/A
A14: 6th bottom dryer felt tension | B14: N/A
A15: Doctor loading pressure | B15: N/A
... A49: Passivation beam 2 nozzle position | B49: N/A

Sheet Ventilation - PD
B1: =COUNTA(B4:B10) -> 7 | D1: =COUNTA(D4:D10) -> 0 | F1: =D1/B1 -> 0
A3: Key parameters/Quality | B3: Loop | D3: Loop in?
A4: Hood exhaust air moisture 1 - SP | B4: N/A
A5: Hood exhaust air moisture 1 - MV | B5: N/A
A6: Hood exhaust air moisture 2 - SP | B6: N/A
A7: Hood exhaust air moisture 2 - MV | B7: N/A
A8: Hood balance (%) | B8: N/A
A9: Pocket ventilator temperature blown - MV | B9: N/A
A10: Pocket ventilator temperature blown - out | B10: N/A

Sheet Ventilation - AD
B1: =COUNTA(B4:B10) -> 7 | D1: =COUNTA(D4:D10) -> 0 | F1: =D1/B1 -> 0
A3: Key parameters/Quality | B3: Loop | D3: Loop in?
A4: Hood exhaust air moisture 1 - SP | B4: N/A
A5: Hood exhaust air moisture 1 - MV | B5: N/A
A6: Hood exhaust air moisture 2 - SP | B6: N/A
A7: Hood exhaust air moisture 2 - MV | B7: N/A
A8: Hood balance (%) | B8: N/A
A9: Pocket ventilator temperature blown - MV | B9: N/A
A10: Pocket ventilator temperature blown - out | B10: N/A

Sheet Sizer
B1: =COUNTA(B4:B30) -> 27 | D1: =COUNTA(D4:D30) -> 0 | F1: =D1/B1 -> 0
A3: Key parameters/Quality | B3: Loop | D3: Loop in?
A4: Nip load | B4: N/A
A5: Nip pressure FS | B5: N/A
A6: Nip pressure BS | B6: N/A
A7: Nip balance (delta) | B7: Calculated
A8: Sizer roll temperature | B8: N/A
A9: Bottom rod loading pressure | B9: N/A
A10: Bottom rod ml/m2 | B10: N/A
A11: Bottom beam starch concentration (MV or SP) in % | B11: N/A
A12: Bottom roll starch application (g/m2) | B12: N/A
A13: Bottom roll starch application (%) | B13: N/A
A14: Starch flow to bottom head | B14: N/A
A15: Bottom head return flow | B15: N/A
... A30: Web tension after sizer | B30: N/A

Sheet Pope Reeler
B1: =COUNTA(B4:B13) -> 10 | D1: =COUNTA(D4:D13) -> 0 | F1: =D1/B1 -> 0
A3: Key parameters/Quality | B3: Loop | D3: Loop in?
A4: Reel web tension | B4: N/A
A5: Reel drum draw | B5: N/A
A6: Drum doctor loading | B6: N/A
A7: Secondary arm loading DS | B7: N/A
A8: Secondary arm loading DS set point | B8: N/A
A9: Secondary arm loading DS output | B9: N/A
A10: Secondary arm loading BS | B10: N/A
A11: Secondary arm loading BS set point | B11: N/A
A12: Secondary arm loading BS output | B12: N/A
A13: Turn up system? | B13: N/A

Sheet Draws and Drives
B1: =COUNTA(B4:B51) -> 46 | D1: =COUNTA(D4:D51) -> 3 | F1: =D1/B1 -> 0.065217391
A3: Key parameters/Quality | B3: Loop | D3: Loop in?
A4: Total draw | B4: CALCULATED ON WEDGE | D4: Y
A5: wire to press draw | B5: N/A
A6: press to shoe press draw | B6: N/A
A7: shoe press to 1st dryer draw | B7: N/A
A8: 1st dryer to 2nd dryer draw | B8: N/A
A9: 2nd dryer top to bottom draw | B9: N/A
A10: 2nd dryer to 3rd dryer draw | B10: N/A
A11: 3rd dryer top to bottom draw | B11: N/A
A12: 3rd dryer to 4th dryer draw | B12: N/A
A13: 4th dryer top to bottom draw | B13: N/A
A14: 4th dryer to sizer draw | B14: N/A
A15: Sizer tension (before) | B15: N/A
A16: Sizer tension (after) | B16: N/A
... A23: Reel drum draw | B23: N/A
A24: Couch speed | B24: Forming section speed | D24: Y
A25: Couch drive load | B25: N/A
A26: Forward drive speed | B26: N/A
A27: Forward drive load | B27: N/A
A28: Pickup roll speed | B28: N/A
A29: Pickup roll drive load | B29: N/A
A30: 1st press speed | B30: N/A
A31: 1st press drive load | B31: N/A
A32: 3rd press speed | B32: N/A
A33: 3rd press drive load | B33: N/A
A34: 1st dryers speed | B34: N/A
A35: 1st dryers drive load | B35: N/A
A36: 2nd dryers speed | B36: N/A
... A47: 6th dryers drive load | B47: N/A
A48: Reel drum speed | B48: POPE_REEL_SPEED | D48: Y
A49: Reel drum drive load | B49: N/A

Sheet Steam consumption
B1: =COUNTA(B4:B26) -> 21 | D1: =COUNTA(E4:E26) -> 9 | F1: =D1/B1 -> 0.42857143
A3: Key parameters/Quality | B3: Loop | C3: Comments | E3: Loop in?
A4: Relative real power consumption | B4: Calculated | C4: No possible, no condensate power back
A5: Relative steam consumption | B5: Calculated | C5: FI411 divided by gross production rate | E5: Y
A6: Total steam consumption - Power Plant transmitter | B6: ="--" -> -- | C6: PowerPlant not in PhD
A7: Total steam consumption - PM transmitter | B7: FI411 | E7: Y
A8: PowerPlant - PM transmitter balance | B8: Calculated | C8: Delta between both transmitters to evaluate callibration and/or detect leaks
A9: Main steam line steam pressure | B9: PI402 | E9: Y
A10: Main steam line steam temperature | B10: TI411 | E10: Y
A11: Condensate back to PowerPlant relative power | B11: Calculated | C11: Not possible, not measurement. Should be power divided by gross prod.
A12: Condensate back to PowerPlant power | C12: At Power Plant
A13: Condensate back to PowerPlant flow | C13: At Power Plant
A14: Codensate back to PowerPlant temperature | B14: TI311 | C14: Not measuring on DCS | E14: Y
A15: Relative PD steam consumption | B15: Calculated | C15: As per PwP recommendations. To be improved when scanner will be in
A16: PD steam consumption | B16: Calculated | C16: No flow transmitter. FI411 minus all.
A17: AD steam consumption | B17: FI514 | C17: In Wedge indicating kg/h but in reality it is tons/h. Needs to be modified in PhD | E17: Y
A18: Auxiliary consumption | B18: FI513 | C18: In Wedge indicating kg/h but in reality it is tons/h. Needs to be modified in PhD | E18: Y
A19: Steam to stock preparation | B19: ="--" -> -- | C19: As per Auxiliary consumption
A20: Steam to WW | B20: ="--" -> -- | C20: No line to heat it
A21: Steam to Warm Water | B21: ="--" -> -- | C21: As per Auxiliary consumption
A22: Steam to steambox | B22: ="--" -> -- | C22: No steambox
A23: Hood ventilation steam consumption | B23: F1512 | C23: In Wedge indicating kg/h but in reality it is tons/h. Needs to be modified in PhD | E23: Y
A24: Steam to heat exchangers | B24: ="--" -> -- | C24: As per Auxiliary consumption
A25: Steam to machine hall | B25: FI511 | C25: In Wedge indicating kg/h but in reality it is tons/h. Needs to be modified in PhD | E25: Y
A26: Steam to starch preparation | B26: ="--" -> -- | C26: As per Auxiliary consumption

Sheet Steam
B1: =COUNTA(B4:B134) -> 117 | D1: =COUNTA(D7:D134) -> 1 | F1: =D1/B1 -> 0.0085470085
A3: Key parameters/Quality | B3: Loop | D3: Loop in?
A5: Pressure
A7: Main steam line pressure | B7: Repeated | D7: Y
A8: Aerothermic main line pressure | B8: N/A
A9: Header pressure before pressure control valve | B9: N/A
A10: Header pressure after pressure control valve | B10: N/A
A11: Cylinder 1 pressure | B11: N/A
A12: Cylinder 1 pressure set point | B12: N/A
A13: Cylinder 1 pressure output | B13: N/A
A14: Cylinder 2 pressure | B14: N/A
A15: Cylinder 2 pressure set point | B15: N/A
A16: Cylinder 2 pressure output | B16: N/A
A17: Cylinder 3 pressure | B17: N/A
A18: Cylinder 3-5 pressure | B18: N/A
A19: Cylinder 3-5 pressure set point | B19: N/A
... A47: Cylinder 33, 35, 37, 39 pressure output | B47: N/A
A50: Differential pressures
A52: Cylinder 1 DP | B52: N/A
A53: Cylinder 1 DP set point | B53: N/A
A54: Cylinder 1 DP output | B54: N/A
A55: Cylinder 2 DP | B55: N/A
A56: Cylinder 2 DP set point | B56: N/A
A57: Cylinder 2 DP output | B57: N/A
A58: Cylinder 3 DP | B58: N/A
A59: Cylinder 3-5 DP | B59: N/A
A60: Cylinder 3-5 DP set point | B60: N/A
A61: Cylinder 3-5 DP output | B61: N/A
A62: Cylinder 7 DP | B62: N/A
A63: Cylinder 6-8 DP | B63: N/A
... A86: Cylinder 33, 35, 37, 39 DP output | B86: N/A
A88: Condensate
A90: Separators
A92: Seprator 1 level | B92: N/A
A93: Seprator 1 level set point | B93: N/A
A94: Seprator 1 level output | B94: N/A
A95: Separator 1 condensate temperature | B95: N/A
A96: Separator 1 condensate temperature output | B96: N/A
A97: Seprator 2 level | B97: N/A
A98: Seprator 2 level set point | B98: N/A
...

Sheet Starch
B1: =COUNTA(B4:B56) -> 53 | D1: =COUNTA(D4:D56) -> 0 | F1: =D1/B1 -> 0
A3: Key parameters/Quality | B3: Loop | D3: Loop in?
A4: Starch usage (t/h) | B4: N/A
A5: Silo level | B5: N/A
A6: Starch powder flow | B6: N/A
A7: Starch powder flow set point | B7: N/A
A8: Starch powder flow output | B8: N/A
A9: Mixing water flow | B9: N/A
A10: Mixing water flow set point | B10: N/A
A11: Mixing water flow output | B11: N/A
A12: Slurry flow | B12: N/A
A13: Slurry flow set point | B13: N/A
A14: Slurry flow output | B14: N/A
A15: Slurry concentration | B15: Calculated
... A56: Flow to metering unit from bottom supply tank - out | B56: N/A

Sheet Chemicals - ret. aid
B1: =COUNTA(B4:B18) -> 15 | D1: =COUNTA(D4:D18) -> 0 | F1: =D1/B1 -> 0
A3: Key parameters/Quality | B3: Loop | D3: Loop in?
A4: Headbox consistency | B4: N/A
A5: WW consistency | B5: N/A
A6: Total retention | B6: N/A
A7: Retention aid batching tank level | B7: N/A
A8: Retention aid dosing tank level | B8: N/A
A9: RETENTION AID bottom ply flow | B9: HB_2515P_BL
A10: RETENTION AID bottom ply flow - out | B10: N/A
A11: Retention aid water flush flow | B11: N/A
A12: Retention aid water flush relative flow | B12: Calculated
A13: Retention aid relative consumption l/t | B13: Calculated
A14: DRY STRENGHT CAT | B14: HERCOBOND_BL
A15: DRY STRENGHT CAT | B15: HERCOBOND_TL
... A18: DRY STRENGHT AN | B18: RETENTIE_TL

Sheet Chemicals - size
B1: =COUNTA(B4:B9) -> 6 | D1: =COUNTA(D4:D9) -> 0 | F1: =D1/B1 -> 0
A3: Key parameters/Quality | B3: Loop | D3: Loop in?
A4: Cobb | B4: COBB
A5: Sizing agent tank level | B5: N/A
A6: SURFACE SIZING AGENT flow | B6: BP450P
A7: SURFACE SIZING AGENT flow - out | B7: N/A
A8: Sizing agent relative consumption per flow (%) | B8: calculated
A9: Sizing agent relative consumption per ton (l/ton) | B9: calculated

Sheet Chemicals - dye
B1: =COUNTA(B4:B17) -> 14 | D1: =COUNTA(D4:D17) -> 3 | F1: =D1/B1 -> 0.21428571
A3: Key parameters/Quality | B3: Loop | D3: Loop in?
A4: QCS color (L) | B4: N/A
A5: QCS color (a) | B5: N/A
A6: QCS color (b) | B6: N/A
A7: Lab color (L) | B7: Lab L | D7: Y
A8: Lab color (a) | B8: Lab a | D8: Y
A9: Lab color (b) | B9: Lab b | D9: Y
A10: Dye black flow | B10: N/A
A11: Dye black flow - out | B11: N/A
A12: Dye yellow flow | B12: N/A
A13: Dye yellow flow - out | B13: N/A
A14: Dye red flow | B14: N/A
A15: Dye red flow - out | B15: N/A
A16: Total dye flow | B16: calculated
A17: Specific dye consumption | B17: calculated

Sheet PM Discfilter
B1: =COUNTA(B4:B20) -> 16 | D1: =COUNTA(D4:D20) -> 13 | F1: =D1/B1 -> 0.8125
A3: Key parameters/Quality | B3: Loop | D3: Loop in?
A4: Disc filter level | B4: LIC1447032.DACA.PV | D4: Y
A5: Disc filter level set point | B5: LIC1447032.PID_PLA.SP | D5: Y
A6: Disc filter level Output | B6: LIC1447032.PID_PLA.OP | D6: Y
A7: Disc filter rotation speed | B7: 1448021_N.DACA.PV | D7: Y
A8: Disc filter water storage tank level( SUPER CLEAR FILTRATE) | B8: LIC1447042.DACA.PV | D8: Y
A9: Disc filter water storage tank levels( CLEAR FILTRATE) | B9: LIC1447040.DACA.PV | D9: Y
A10: Disc filter water storage tank levels( CLOUDY FILTRATE) | B10: LIC1447036.DACA.PV | D10: Y
A11: Disc filter shower pressures | B11: PI1447033.DACA.PV | D11: Y
A13: Disc filter screw dilution water flow | B13: FIC1417129.DACA.PV | D13: Y
A14: Disc filter recovered fibre level | B14: LIC1447031.DACA.PV | D14: Y
A15: Disc filter recovered fibre level set point | B15: LIC1447031.PID_PLA.SP | D15: Y
A16: Disc filter recovered fibre level output | B16: LIC1447031.PID_PLA.OP | D16: Y
A17: Disc filter recovered fibre consistency | B17: N/A
A18: Disc filter recovered fibre consistency set point | B18: N/A
A19: Disc filter recovered fibre consistency output | B19: N/A
A20: Disc filter inlet flow | B20: FI1317182.DACA.PV | D20: Y

Sheet Vacuum pumps
A3: Key parameters/Quality | B3: Loop | D3: Loop in?
A5: Freshwater to vacuum pumps flow | B5: on wedge | D5: ="--" -> --
A6: Sealing water temperature | B6: on wedge | D6: ="--" -> --
A7: Sealing water pressure | B7: on wedge | D7: ="--" -> --
A8: Discharge channel level | B8: on wedge | D8: ="--" -> --
A9: Blower BL | B9: on wedge | D9: ="--" -> --
A10: Blower TL | B10: on wedge | D10: ="--" -> --
A11: Vacuum pump currents
A12: Vacuum pump 0 Cutes rotor currrent | B12: on wedge | D12: ="--" -> --
A13: Vacuum pump 1 Garuda rotor current | B13: on wedge | D13: ="--" -> --
A14: Vacuum pump 2 Garuda rotor current | B14: on wedge | D14: ="--" -> --
A15: Vacuum pump 3 Nash mica rotor current | B15: on wedge | D15: ="--" -> --
A16: Vacuum pump 4 Nash mica rotor current | B16: on wedge | D16: ="--" -> --
A17: Vacuum pump 5 Nash mica rotor current | B17: on wedge | D17: ="--" -> --
A18: Vacuum pump 6 Nash mica rotor current | B18: on wedge | D18: ="--" -> --
A19: Vacuum pump 7 Nash mica rotor current | B19: on wedge | D19: ="--" -> --
A20: Water to Vacuum pumps
A21: Water to vacuum pump 0 | B21: on wedge | D21: ="--" -> --
A22: Water to vacuum pump 0 | B22: on wedge | D22: ="--" -> --
A23: Water to vacuum pump 1 | B23: on wedge | D23: ="--" -> --
A24: Water to vacuum pump 1 | B24: on wedge | D24: ="--" -> --
A25: Water to vacuum pump 2 | B25: on wedge | D25: ="--" -> --
A26: Water to vacuum pump 2 | B26: on wedge | D26: ="--" -> --
A27: Water to vacuum pump 3 | B27: on wedge | D27: ="--" -> --
A28: Water to vacuum pump 3 | B28: on wedge | D28: ="--" -> --
A29: Water to vacuum pump 4 | B29: on wedge | D29: ="--" -> --
A30: Water to vacuum pump 4 | B30: on wedge | D30: ="--" -> --
A31: Water to vacuum pump 5 | B31: on wedge | D31: ="--" -> --
A32: Water to vacuum pump 5 | B32: on wedge | D32: ="--" -> --
... A36: Water to vacuum pump 7 | B36: on wedge | D36: ="--" -> --
A37: Separators
A38: Vacuum pump 1 vacuum | B38: on wedge | D38: ="--" -> --
A39: Vacuum pump 2 vacuum | B39: on wedge | D39: ="--" -> --
A40: Vacuum pump 3 couch roll zone 1 vacuum | B40: on wedge | D40: ="--" -> --
A41: Vacuum pump 3 couch roll zone 2 vacuum | B41: on wedge | D41: ="--" -> --
A42: Vacuum pump 4 vacuum | B42: on wedge | D42: ="--" -> --
A43: Vacuum pump 5 vacuum | B43: on wedge | D43: ="--" -> --
A44: Vacuum pump 6 1st press suction holding zone vacuum | B44: on wedge | D44: ="--" -> --
A45: Vacuum pump 6 shoe press bottom felt uhle box vacuum | B45: on wedge | D45: ="--" -> --
A46: Vacuum pump 7 1st press bottom felt uhle box vacuum | B46: on wedge | D46: ="--" -> --
...

Sheet Break detectors
A3: Key parameters/Quality | B3: Loop | D3: Loop in?
A4: Wetend break detector | B4: N/A | D4: ="--" -> --
A5: dryend break detector | B5: N/A | D5: ="--" -> --
A6: reel drum break detector | B6: N/A | D6: ="--" -> --
A7: BREAK SIGNAL FROM PHOTOCELL/BYTE SIGNAL | B7: BREAK_SIGNAL | D7: ="--" -> --
